Workbook

Sheet DASHBOARD
A1: CENTRO DE MANDO — PROGRAMA DE HIPERTROFIA Y RECOMPOSICION CORPORAL
A2: Inicio: Mie 25/03/2026 | 8 Microciclos | Fuente 12
A4: KPIs NUTRICIONALES DIARIOS
A5: CALORIAS TARGET | D5: PROTEINA | G5: GRASA | J5: CARBOHIDRATOS | M5: % BF INICIAL
A6: 1,850 Kcal | D6: 135 g | G6: 40 g | J6: 235 g | M6: 12.0 %
A8: EVOLUCION PESO CORPORAL (kg) | J8: EVOLUCION % GRASA CORPORAL (BF%)
A9: Microciclo | B9: Peso Prom (kg) | C9: BF% Estimado
A10: MC01 | B10: =IF(TRACKER!B20="","",TRACKER!B20) -> 52.842857 | C10: =IF(TRACKER!B20="","",ROUND(TRACKER!$D$4-((TRACKER!$B$4-TRACKER!B20)/TRACKER!$B$4)*100,1)) -> 10.4
A11: MC02 | B11: =IF(TRACKER!B30="","",TRACKER!B30) -> 53.157143 | C11: =IF(TRACKER!B30="","",ROUND(TRACKER!$D$4-((TRACKER!$B$4-TRACKER!B30)/TRACKER!$B$4)*100,1)) -> 11
A12: MC03 | B12: =IF(TRACKER!B40="","",TRACKER!B40) -> 52.985714 | C12: =IF(TRACKER!B40="","",ROUND(TRACKER!$D$4-((TRACKER!$B$4-TRACKER!B40)/TRACKER!$B$4)*100,1)) -> 10.7
A13: MC04 | B13: =IF(TRACKER!B50="","",TRACKER!B50) -> 53.166667 | C13: =IF(TRACKER!B50="","",ROUND(TRACKER!$D$4-((TRACKER!$B$4-TRACKER!B50)/TRACKER!$B$4)*100,1)) -> 11
A14: MC05 | B14: =IF(TRACKER!B60="","",TRACKER!B60) | C14: =IF(TRACKER!B60="","",ROUND(TRACKER!$D$4-((TRACKER!$B$4-TRACKER!B60)/TRACKER!$B$4)*100,1))
A15: MC06 | B15: =IF(TRACKER!B70="","",TRACKER!B70) | C15: =IF(TRACKER!B70="","",ROUND(TRACKER!$D$4-((TRACKER!$B$4-TRACKER!B70)/TRACKER!$B$4)*100,1))
A16: MC07 | B16: =IF(TRACKER!B80="","",TRACKER!B80) | C16: =IF(TRACKER!B80="","",ROUND(TRACKER!$D$4-((TRACKER!$B$4-TRACKER!B80)/TRACKER!$B$4)*100,1))
A17: MC08 | B17: =IF(TRACKER!B90="","",TRACKER!B90) | C17: =IF(TRACKER!B90="","",ROUND(TRACKER!$D$4-((TRACKER!$B$4-TRACKER!B90)/TRACKER!$B$4)*100,1))
A30: TABLA DE PROGRESION — TONELAJE POR EJERCICIO Y MICROCICLO (Reps x Kg)
A31: DIA | B31: EJERCICIO | C31: MC01 Ton.kg | D31: MC01 Estado | E31: MC02 Ton.kg | F31: MC02 Estado | G31: MC03 Ton.kg | H31: MC03 Estado | I31: MC04 Ton.kg | J31: MC04 Estado | K31: MC05 Ton.kg | L31: MC05 Estado | M31: MC06 Ton.kg | N31: MC06 Estado | O31: MC07 Ton.kg | P31: MC07 Estado | Q31: MC08 Ton.kg | R31: MC08 Estado
A32: DAY 1 | B32: Zancadas con mancuernas | C32: ='DAY 1'!M6 -> 0 | D32: — | E32: ='DAY 1'!M16 -> 540 | F32: =IF(OR(E32=0,C32=0),"—",IF(E32>C32,"RENDIMIENTO SUPERIOR",IF(E32=C32,"MANTENIMIENTO","DEFICIT"))) -> — | G32: ='DAY 1'!M26 -> 540 | H32: =IF(OR(G32=0,E32=0),"—",IF(G32>E32,"RENDIMIENTO SUPERIOR",IF(G32=E32,"MANTENIMIENTO","DEFICIT"))) -> MANTENIMIENTO | I32: ='DAY 1'!M36 -> 540 | J32: =IF(OR(I32=0,G32=0),"—",IF(I32>G32,"RENDIMIENTO SUPERIOR",IF(I32=G32,"MANTENIMIENTO","DEFICIT"))) -> MANTENIMIENTO | K32: ='DAY 1'!M46 -> 540 | L32: =IF(OR(K32=0,I32=0),"—",IF(K32>I32,"RENDIMIENTO SUPERIOR",IF(K32=I32,"MANTENIMIENTO","DEFICIT"))) -> MANTENIMIENTO | M32: ='DAY 1'!M56 | N32: =IF(OR(M32=0,K32=0),"—",IF(M32>K32,"RENDIMIENTO SUPERIOR",IF(M32=K32,"MANTENIMIENTO","DEFICIT"))) -> — | O32: ='DAY 1'!M66 | P32: =IF(OR(O32=0,M32=0),"—",IF(O32>M32,"RENDIMIENTO SUPERIOR",IF(O32=M32,"MANTENIMIENTO","DEFICIT"))) -> — | Q32: ='DAY 1'!M76 -> 0 | R32: =IF(OR(Q32=0,O32=0),"—",IF(Q32>O32,"RENDIMIENTO SUPERIOR",IF(Q32=O32,"MANTENIMIENTO","DEFICIT"))) -> —
A33: DAY 1 | B33: Extension de cuadriceps en maquina | C33: ='DAY 1'!M7 -> 0 | D33: — | E33: ='DAY 1'!M17 -> 1620 | F33: =IF(OR(E33=0,C33=0),"—",IF(E33>C33,"RENDIMIENTO SUPERIOR",IF(E33=C33,"MANTENIMIENTO","DEFICIT"))) -> — | G33: ='DAY 1'!M27 -> 2127.5 | H33: =IF(OR(G33=0,E33=0),"—",IF(G33>E33,"RENDIMIENTO SUPERIOR",IF(G33=E33,"MANTENIMIENTO","DEFICIT"))) -> RENDIMIENTO SUPERIOR | I33: ='DAY 1'!M37 -> 2130 | J33: =IF(OR(I33=0,G33=0),"—",IF(I33>G33,"RENDIMIENTO SUPERIOR",IF(I33=G33,"MANTENIMIENTO","DEFICIT"))) -> RENDIMIENTO SUPERIOR | K33: ='DAY 1'!M47 -> 2190 | L33: =IF(OR(K33=0,I33=0),"—",IF(K33>I33,"RENDIMIENTO SUPERIOR",IF(K33=I33,"MANTENIMIENTO","DEFICIT"))) -> RENDIMIENTO SUPERIOR | M33: ='DAY 1'!M57 -> 0 | N33: =IF(OR(M33=0,K33=0),"—",IF(M33>K33,"RENDIMIENTO SUPERIOR",IF(M33=K33,"MANTENIMIENTO","DEFICIT"))) -> — | O33: ='DAY 1'!M67 | P33: =IF(OR(O33=0,M33=0),"—",IF(O33>M33,"RENDIMIENTO SUPERIOR",IF(O33=M33,"MANTENIMIENTO","DEFICIT"))) -> — | Q33: ='DAY 1'!M77 | R33: =IF(OR(Q33=0,O33=0),"—",IF(Q33>O33,"RENDIMIENTO SUPERIOR",IF(Q33=O33,"MANTENIMIENTO","DEFICIT"))) -> —
A34: DAY 1 | B34: Curl femoral tumbado en maquina | C34: ='DAY 1'!M8 -> 0 | D34: — | E34: ='DAY 1'!M18 -> 675 | F34: =IF(OR(E34=0,C34=0),"—",IF(E34>C34,"RENDIMIENTO SUPERIOR",IF(E34=C34,"MANTENIMIENTO","DEFICIT"))) -> — | G34: ='DAY 1'!M28 -> 675 | H34: =IF(OR(G34=0,E34=0),"—",IF(G34>E34,"RENDIMIENTO SUPERIOR",IF(G34=E34,"MANTENIMIENTO","DEFICIT"))) -> MANTENIMIENTO | I34: ='DAY 1'!M38 -> 675 | J34: =IF(OR(I34=0,G34=0),"—",IF(I34>G34,"RENDIMIENTO SUPERIOR",IF(I34=G34,"MANTENIMIENTO","DEFICIT"))) -> MANTENIMIENTO | K34: ='DAY 1'!M48 -> 1050 | L34: =IF(OR(K34=0,I34=0),"—",IF(K34>I34,"RENDIMIENTO SUPERIOR",IF(K34=I34,"MANTENIMIENTO","DEFICIT"))) -> RENDIMIENTO SUPERIOR | M34: ='DAY 1'!M58 -> 0 | N34: =IF(OR(M34=0,K34=0),"—",IF(M34>K34,"RENDIMIENTO SUPERIOR",IF(M34=K34,"MANTENIMIENTO","DEFICIT"))) -> — | O34: ='DAY 1'!M68 -> 0 | P34: =IF(OR(O34=0,M34=0),"—",IF(O34>M34,"RENDIMIENTO SUPERIOR",IF(O34=M34,"MANTENIMIENTO","DEFICIT"))) -> — | Q34: ='DAY 1'!M78 | R34: =IF(OR(Q34=0,O34=0),"—",IF(Q34>O34,"RENDIMIENTO SUPERIOR",IF(Q34=O34,"MANTENIMIENTO","DEFICIT"))) -> —
A35: DAY 1 | B35: Elevaciones laterales con mancuerna | C35: ='DAY 1'!M9 -> 0 | D35: — | E35: ='DAY 1'!M19 -> 360 | F35: =IF(OR(E35=0,C35=0),"—",IF(E35>C35,"RENDIMIENTO SUPERIOR",IF(E35=C35,"MANTENIMIENTO","DEFICIT"))) -> — | G35: ='DAY 1'!M29 -> 450 | H35: =IF(OR(G35=0,E35=0),"—",IF(G35>E35,"RENDIMIENTO SUPERIOR",IF(G35=E35,"MANTENIMIENTO","DEFICIT"))) -> RENDIMIENTO SUPERIOR | I35: ='DAY 1'!M39 -> 450 | J35: =IF(OR(I35=0,G35=0),"—",IF(I35>G35,"RENDIMIENTO SUPERIOR",IF(I35=G35,"MANTENIMIENTO","DEFICIT"))) -> MANTENIMIENTO | K35: ='DAY 1'!M49 -> 450 | L35: =IF(OR(K35=0,I35=0),"—",IF(K35>I35,"RENDIMIENTO SUPERIOR",IF(K35=I35,"MANTENIMIENTO","DEFICIT"))) -> MANTENIMIENTO | M35: ='DAY 1'!M59 -> 0 | N35: =IF(OR(M35=0,K35=0),"—",IF(M35>K35,"RENDIMIENTO SUPERIOR",IF(M35=K35,"MANTENIMIENTO","DEFICIT"))) -> — | O35: ='DAY 1'!M69 -> 0 | P35: =IF(OR(O35=0,M35=0),"—",IF(O35>M35,"RENDIMIENTO SUPERIOR",IF(O35=M35,"MANTENIMIENTO","DEFICIT"))) -> — | Q35: ='DAY 1'!M79 -> 0 | R35: =IF(OR(Q35=0,O35=0),"—",IF(Q35>O35,"RENDIMIENTO SUPERIOR",IF(Q35=O35,"MANTENIMIENTO","DEFICIT"))) -> —
A36: DAY 1 | B36: Elevaciones laterales en polea baja | C36: ='DAY 1'!M10 -> 0 | D36: — | E36: ='DAY 1'!M20 -> 517.5 | F36: =IF(OR(E36=0,C36=0),"—",IF(E36>C36,"RENDIMIENTO SUPERIOR",IF(E36=C36,"MANTENIMIENTO","DEFICIT"))) -> — | G36: ='DAY 1'!M30 -> 622.5 | H36: =IF(OR(G36=0,E36=0),"—",IF(G36>E36,"RENDIMIENTO SUPERIOR",IF(G36=E36,"MANTENIMIENTO","DEFICIT"))) -> RENDIMIENTO SUPERIOR | I36: ='DAY 1'!M40 -> 517.5 | J36: =IF(OR(I36=0,G36=0),"—",IF(I36>G36,"RENDIMIENTO SUPERIOR",IF(I36=G36,"MANTENIMIENTO","DEFICIT"))) -> DEFICIT | K36: ='DAY 1'!M50 -> 540 | L36: =IF(OR(K36=0,I36=0),"—",IF(K36>I36,"RENDIMIENTO SUPERIOR",IF(K36=I36,"MANTENIMIENTO","DEFICIT"))) -> RENDIMIENTO SUPERIOR | M36: ='DAY 1'!M60 -> 0 | N36: =IF(OR(M36=0,K36=0),"—",IF(M36>K36,"RENDIMIENTO SUPERIOR",IF(M36=K36,"MANTENIMIENTO","DEFICIT"))) -> — | O36: ='DAY 1'!M70 -> 0 | P36: =IF(OR(O36=0,M36=0),"—",IF(O36>M36,"RENDIMIENTO SUPERIOR",IF(O36=M36,"MANTENIMIENTO","DEFICIT"))) -> — | Q36: ='DAY 1'!M80 -> 0 | R36: =IF(OR(Q36=0,O36=0),"—",IF(Q36>O36,"RENDIMIENTO SUPERIOR",IF(Q36=O36,"MANTENIMIENTO","DEFICIT"))) -> —
A37: DAY 1 | B37: Elevaciones laterales en polea media | C37: ='DAY 1'!M11 -> 0 | D37: — | E37: ='DAY 1'!M21 -> 675 | F37: =IF(OR(E37=0,C37=0),"—",IF(E37>C37,"RENDIMIENTO SUPERIOR",IF(E37=C37,"MANTENIMIENTO","DEFICIT"))) -> — | G37: ='DAY 1'!M31 -> 677.5 | H37: =IF(OR(G37=0,E37=0),"—",IF(G37>E37,"RENDIMIENTO SUPERIOR",IF(G37=E37,"MANTENIMIENTO","DEFICIT"))) -> RENDIMIENTO SUPERIOR | I37: ='DAY 1'!M41 -> 750 | J37: =IF(OR(I37=0,G37=0),"—",IF(I37>G37,"RENDIMIENTO SUPERIOR",IF(I37=G37,"MANTENIMIENTO","DEFICIT"))) -> RENDIMIENTO SUPERIOR | K37: ='DAY 1'!M51 -> 2475 | L37: =IF(OR(K37=0,I37=0),"—",IF(K37>I37,"RENDIMIENTO SUPERIOR",IF(K37=I37,"MANTENIMIENTO","DEFICIT"))) -> RENDIMIENTO SUPERIOR | M37: ='DAY 1'!M61 -> 0 | N37: =IF(OR(M37=0,K37=0),"—",IF(M37>K37,"RENDIMIENTO SUPERIOR",IF(M37=K37,"MANTENIMIENTO","DEFICIT"))) -> — | O37: ='DAY 1'!M71 -> 0 | P37: =IF(OR(O37=0,M37=0),"—",IF(O37>M37,"RENDIMIENTO SUPERIOR",IF(O37=M37,"MANTENIMIENTO","DEFICIT"))) -> — | Q37: ='DAY 1'!M81 -> 0 | R37: =IF(OR(Q37=0,O37=0),"—",IF(Q37>O37,"RENDIMIENTO SUPERIOR",IF(Q37=O37,"MANTENIMIENTO","DEFICIT"))) -> —
A38: DAY 1 | B38: Crunch abdominal en polea | C38: ='DAY 1'!M12 -> 0 | D38: — | E38: ='DAY 1'!M22 -> 2932.5 | F38: =IF(OR(E38=0,C38=0),"—",IF(E38>C38,"RENDIMIENTO SUPERIOR",IF(E38=C38,"MANTENIMIENTO","DEFICIT"))) -> — | G38: ='DAY 1'!M32 -> 2645 | H38: =IF(OR(G38=0,E38=0),"—",IF(G38>E38,"RENDIMIENTO SUPERIOR",IF(G38=E38,"MANTENIMIENTO","DEFICIT"))) -> DEFICIT | I38: ='DAY 1'!M42 -> 2760 | J38: =IF(OR(I38=0,G38=0),"—",IF(I38>G38,"RENDIMIENTO SUPERIOR",IF(I38=G38,"MANTENIMIENTO","DEFICIT"))) -> RENDIMIENTO SUPERIOR | K38: ='DAY 1'!M52 -> 900 | L38: =IF(OR(K38=0,I38=0),"—",IF(K38>I38,"RENDIMIENTO SUPERIOR",IF(K38=I38,"MANTENIMIENTO","DEFICIT"))) -> DEFICIT | M38: ='DAY 1'!M62 -> 0 | N38: =IF(OR(M38=0,K38=0),"—",IF(M38>K38,"RENDIMIENTO SUPERIOR",IF(M38=K38,"MANTENIMIENTO","DEFICIT"))) -> — | O38: ='DAY 1'!M72 -> 0 | P38: =IF(OR(O38=0,M38=0),"—",IF(O38>M38,"RENDIMIENTO SUPERIOR",IF(O38=M38,"MANTENIMIENTO","DEFICIT"))) -> — | Q38: ='DAY 1'!M82 -> 0 | R38: =IF(OR(Q38=0,O38=0),"—",IF(Q38>O38,"RENDIMIENTO SUPERIOR",IF(Q38=O38,"MANTENIMIENTO","DEFICIT"))) -> —
A39: DAY 2 | B39: Jalon al pecho con agarre neutro | C39: ='DAY 2'!M6 -> 0 | D39: — | E39: ='DAY 2'!M16 -> 2340 | F39: =IF(OR(E39=0,C39=0),"—",IF(E39>C39,"RENDIMIENTO SUPERIOR",IF(E39=C39,"MANTENIMIENTO","DEFICIT"))) -> — | G39: ='DAY 2'!M26 -> 2100 | H39: =IF(OR(G39=0,E39=0),"—",IF(G39>E39,"RENDIMIENTO SUPERIOR",IF(G39=E39,"MANTENIMIENTO","DEFICIT"))) -> DEFICIT | I39: ='DAY 2'!M36 -> 2450 | J39: =IF(OR(I39=0,G39=0),"—",IF(I39>G39,"RENDIMIENTO SUPERIOR",IF(I39=G39,"MANTENIMIENTO","DEFICIT"))) -> RENDIMIENTO SUPERIOR | K39: ='DAY 2'!M46 -> 0 | L39: =IF(OR(K39=0,I39=0),"—",IF(K39>I39,"RENDIMIENTO SUPERIOR",IF(K39=I39,"MANTENIMIENTO","DEFICIT"))) -> — | M39: ='DAY 2'!M56 | N39: =IF(OR(M39=0,K39=0),"—",IF(M39>K39,"RENDIMIENTO SUPERIOR",IF(M39=K39,"MANTENIMIENTO","DEFICIT"))) -> — | O39: ='DAY 2'!M66 -> 0 | P39: =IF(OR(O39=0,M39=0),"—",IF(O39>M39,"RENDIMIENTO SUPERIOR",IF(O39=M39,"MANTENIMIENTO","DEFICIT"))) -> — | Q39: ='DAY 2'!M76 -> 0 | R39: =IF(OR(Q39=0,O39=0),"—",IF(Q39>O39,"RENDIMIENTO SUPERIOR",IF(Q39=O39,"MANTENIMIENTO","DEFICIT"))) -> —
A40: DAY 2 | B40: Remo en maquina con apoyo en el pecho | C40: ='DAY 2'!M7 -> 0 | D40: — | E40: ='DAY 2'!M17 -> 1800 | F40: =IF(OR(E40=0,C40=0),"—",IF(E40>C40,"RENDIMIENTO SUPERIOR",IF(E40=C40,"MANTENIMIENTO","DEFICIT"))) -> — | G40: ='DAY 2'!M27 -> 1860 | H40: =IF(OR(G40=0,E40=0),"—",IF(G40>E40,"RENDIMIENTO SUPERIOR",IF(G40=E40,"MANTENIMIENTO","DEFICIT"))) -> RENDIMIENTO SUPERIOR | I40: ='DAY 2'!M37 -> 2400 | J40: =IF(OR(I40=0,G40=0),"—",IF(I40>G40,"RENDIMIENTO SUPERIOR",IF(I40=G40,"MANTENIMIENTO","DEFICIT"))) -> RENDIMIENTO SUPERIOR | K40: ='DAY 2'!M47 -> 0 | L40: =IF(OR(K40=0,I40=0),"—",IF(K40>I40,"RENDIMIENTO SUPERIOR",IF(K40=I40,"MANTENIMIENTO","DEFICIT"))) -> — | M40: ='DAY 2'!M57 | N40: =IF(OR(M40=0,K40=0),"—",IF(M40>K40,"RENDIMIENTO SUPERIOR",IF(M40=K40,"MANTENIMIENTO","DEFICIT"))) -> — | O40: ='DAY 2'!M67 -> 0 | P40: =IF(OR(O40=0,M40=0),"—",IF(O40>M40,"RENDIMIENTO SUPERIOR",IF(O40=M40,"MANTENIMIENTO","DEFICIT"))) -> — | Q40: ='DAY 2'!M77 -> 0 | R40: =IF(OR(Q40=0,O40=0),"—",IF(Q40>O40,"RENDIMIENTO SUPERIOR",IF(Q40=O40,"MANTENIMIENTO","DEFICIT"))) -> —
A41: DAY 2 | B41: Remo Gironda en polea baja | C41: ='DAY 2'!M8 -> 0 | D41: — | E41: ='DAY 2'!M18 -> 2200 | F41: =IF(OR(E41=0,C41=0),"—",IF(E41>C41,"RENDIMIENTO SUPERIOR",IF(E41=C41,"MANTENIMIENTO","DEFICIT"))) -> — | G41: ='DAY 2'!M28 -> 2640 | H41: =IF(OR(G41=0,E41=0),"—",IF(G41>E41,"RENDIMIENTO SUPERIOR",IF(G41=E41,"MANTENIMIENTO","DEFICIT"))) -> RENDIMIENTO SUPERIOR | I41: ='DAY 2'!M38 -> 2880 | J41: =IF(OR(I41=0,G41=0),"—",IF(I41>G41,"RENDIMIENTO SUPERIOR",IF(I41=G41,"MANTENIMIENTO","DEFICIT"))) -> RENDIMIENTO SUPERIOR | K41: ='DAY 2'!M48 -> 0 | L41: =IF(OR(K41=0,I41=0),"—",IF(K41>I41,"RENDIMIENTO SUPERIOR",IF(K41=I41,"MANTENIMIENTO","DEFICIT"))) -> — | M41: ='DAY 2'!M58 -> 0 | N41: =IF(OR(M41=0,K41=0),"—",IF(M41>K41,"RENDIMIENTO SUPERIOR",IF(M41=K41,"MANTENIMIENTO","DEFICIT"))) -> — | O41: ='DAY 2'!M68 | P41: =IF(OR(O41=0,M41=0),"—",IF(O41>M41,"RENDIMIENTO SUPERIOR",IF(O41=M41,"MANTENIMIENTO","DEFICIT"))) -> — | Q41: ='DAY 2'!M78 -> 0 | R41: =IF(OR(Q41=0,O41=0),"—",IF(Q41>O41,"RENDIMIENTO SUPERIOR",IF(Q41=O41,"MANTENIMIENTO","DEFICIT"))) -> —
A42: DAY 2 | B42: Pull-over con cuerda en polea alta | C42: ='DAY 2'!M9 -> 0 | D42: — | E42: ='DAY 2'!M19 -> 1080 | F42: =IF(OR(E42=0,C42=0),"—",IF(E42>C42,"RENDIMIENTO SUPERIOR",IF(E42=C42,"MANTENIMIENTO","DEFICIT"))) -> — | G42: ='DAY 2'!M29 -> 1105 | H42: =IF(OR(G42=0,E42=0),"—",IF(G42>E42,"RENDIMIENTO SUPERIOR",IF(G42=E42,"MANTENIMIENTO","DEFICIT"))) -> RENDIMIENTO SUPERIOR | I42: ='DAY 2'!M39 -> 1080 | J42: =IF(OR(I42=0,G42=0),"—",IF(I42>G42,"RENDIMIENTO SUPERIOR",IF(I42=G42,"MANTENIMIENTO","DEFICIT"))) -> DEFICIT | K42: ='DAY 2'!M49 -> 0 | L42: =IF(OR(K42=0,I42=0),"—",IF(K42>I42,"RENDIMIENTO SUPERIOR",IF(K42=I42,"MANTENIMIENTO","DEFICIT"))) -> — | M42: ='DAY 2'!M59 -> 0 | N42: =IF(OR(M42=0,K42=0),"—",IF(M42>K42,"RENDIMIENTO SUPERIOR",IF(M42=K42,"MANTENIMIENTO","DEFICIT"))) -> — | O42: ='DAY 2'!M69 | P42: =IF(OR(O42=0,M42=0),"—",IF(O42>M42,"RENDIMIENTO SUPERIOR",IF(O42=M42,"MANTENIMIENTO","DEFICIT"))) -> — | Q42: ='DAY 2'!M79 -> 0 | R42: =IF(OR(Q42=0,O42=0),"—",IF(Q42>O42,"RENDIMIENTO SUPERIOR",IF(Q42=O42,"MANTENIMIENTO","DEFICIT"))) -> —
A43: DAY 2 | B43: Pajaros para deltoide posterior en maquina | C43: ='DAY 2'!M10 -> 0 | D43: — | E43: ='DAY 2'!M20 -> 1050 | F43: =IF(OR(E43=0,C43=0),"—",IF(E43>C43,"RENDIMIENTO SUPERIOR",IF(E43=C43,"MANTENIMIENTO","DEFICIT"))) -> — | G43: ='DAY 2'!M30 -> 1260 | H43: =IF(OR(G43=0,E43=0),"—",IF(G43>E43,"RENDIMIENTO SUPERIOR",IF(G43=E43,"MANTENIMIENTO","DEFICIT"))) -> RENDIMIENTO SUPERIOR | I43: ='DAY 2'!M40 -> 1260 | J43: =IF(OR(I43=0,G43=0),"—",IF(I43>G43,"RENDIMIENTO SUPERIOR",IF(I43=G43,"MANTENIMIENTO","DEFICIT"))) -> MANTENIMIENTO | K43: ='DAY 2'!M50 -> 0 | L43: =IF(OR(K43=0,I43=0),"—",IF(K43>I43,"RENDIMIENTO SUPERIOR",IF(K43=I43,"MANTENIMIENTO","DEFICIT"))) -> — | M43: ='DAY 2'!M60 -> 0 | N43: =IF(OR(M43=0,K43=0),"—",IF(M43>K43,"RENDIMIENTO SUPERIOR",IF(M43=K43,"MANTENIMIENTO","DEFICIT"))) -> — | O43: ='DAY 2'!M70 -> 0 | P43: =IF(OR(O43=0,M43=0),"—",IF(O43>M43,"RENDIMIENTO SUPERIOR",IF(O43=M43,"MANTENIMIENTO","DEFICIT"))) -> — | Q43: ='DAY 2'!M80 | R43: =IF(OR(Q43=0,O43=0),"—",IF(Q43>O43,"RENDIMIENTO SUPERIOR",IF(Q43=O43,"MANTENIMIENTO","DEFICIT"))) -> —
A44: DAY 2 | B44: Curl Scott en maquina | C44: ='DAY 2'!M11 -> 0 | D44: — | E44: ='DAY 2'!M21 -> 540 | F44: =IF(OR(E44=0,C44=0),"—",IF(E44>C44,"RENDIMIENTO SUPERIOR",IF(E44=C44,"MANTENIMIENTO","DEFICIT"))) -> — | G44: ='DAY 2'!M31 -> 540 | H44: =IF(OR(G44=0,E44=0),"—",IF(G44>E44,"RENDIMIENTO SUPERIOR",IF(G44=E44,"MANTENIMIENTO","DEFICIT"))) -> MANTENIMIENTO | I44: ='DAY 2'!M41 -> 540 | J44: =IF(OR(I44=0,G44=0),"—",IF(I44>G44,"RENDIMIENTO SUPERIOR",IF(I44=G44,"MANTENIMIENTO","DEFICIT"))) -> MANTENIMIENTO | K44: ='DAY 2'!M51 -> 0 | L44: =IF(OR(K44=0,I44=0),"—",IF(K44>I44,"RENDIMIENTO SUPERIOR",IF(K44=I44,"MANTENIMIENTO","DEFICIT"))) -> — | M44: ='DAY 2'!M61 -> 0 | N44: =IF(OR(M44=0,K44=0),"—",IF(M44>K44,"RENDIMIENTO SUPERIOR",IF(M44=K44,"MANTENIMIENTO","DEFICIT"))) -> — | O44: ='DAY 2'!M71 -> 0 | P44: =IF(OR(O44=0,M44=0),"—",IF(O44>M44,"RENDIMIENTO SUPERIOR",IF(O44=M44,"MANTENIMIENTO","DEFICIT"))) -> — | Q44: ='DAY 2'!M81 | R44: =IF(OR(Q44=0,O44=0),"—",IF(Q44>O44,"RENDIMIENTO SUPERIOR",IF(Q44=O44,"MANTENIMIENTO","DEFICIT"))) -> —
A45: DAY 2 | B45: Rueda abdominal | C45: ='DAY 2'!M12 -> 0 | D45: — | E45: ='DAY 2'!M22 -> 2475 | F45: =IF(OR(E45=0,C45=0),"—",IF(E45>C45,"RENDIMIENTO SUPERIOR",IF(E45=C45,"MANTENIMIENTO","DEFICIT"))) -> — | G45: ='DAY 2'!M32 -> 1980 | H45: =IF(OR(G45=0,E45=0),"—",IF(G45>E45,"RENDIMIENTO SUPERIOR",IF(G45=E45,"MANTENIMIENTO","DEFICIT"))) -> DEFICIT | I45: ='DAY 2'!M42 -> 1980 | J45: =IF(OR(I45=0,G45=0),"—",IF(I45>G45,"RENDIMIENTO SUPERIOR",IF(I45=G45,"MANTENIMIENTO","DEFICIT"))) -> MANTENIMIENTO | K45: ='DAY 2'!M52 -> 0 | L45: =IF(OR(K45=0,I45=0),"—",IF(K45>I45,"RENDIMIENTO SUPERIOR",IF(K45=I45,"MANTENIMIENTO","DEFICIT"))) -> — | M45: ='DAY 2'!M62 -> 0 | N45: =IF(OR(M45=0,K45=0),"—",IF(M45>K45,"RENDIMIENTO SUPERIOR",IF(M45=K45,"MANTENIMIENTO","DEFICIT"))) -> — | O45: ='DAY 2'!M72 -> 0 | P45: =IF(OR(O45=0,M45=0),"—",IF(O45>M45,"RENDIMIENTO SUPERIOR",IF(O45=M45,"MANTENIMIENTO","DEFICIT"))) -> — | Q45: ='DAY 2'!M82 -> 0 | R45: =IF(OR(Q45=0,O45=0),"—",IF(Q45>O45,"RENDIMIENTO SUPERIOR",IF(Q45=O45,"MANTENIMIENTO","DEFICIT"))) -> —
A46: DAY 3 | B46: Press plano en maquina | C46: ='DAY 3'!M6 -> 0 | D46: — | E46: ='DAY 3'!M19 -> 1200 | F46: =IF(OR(E46=0,C46=0),"—",IF(E46>C46,"RENDIMIENTO SUPERIOR",IF(E46=C46,"MANTENIMIENTO","DEFICIT"))) -> — | G46: ='DAY 3'!M32 -> 1380 | H46: =IF(OR(G46=0,E46=0),"—",IF(G46>E46,"RENDIMIENTO SUPERIOR",IF(G46=E46,"MANTENIMIENTO","DEFICIT"))) -> RENDIMIENTO SUPERIOR | I46: ='DAY 3'!M45 -> 1600 | J46: =IF(OR(I46=0,G46=0),"—",IF(I46>G46,"RENDIMIENTO SUPERIOR",IF(I46=G46,"MANTENIMIENTO","DEFICIT"))) -> RENDIMIENTO SUPERIOR | K46: ='DAY 3'!M58 -> 0 | L46: =IF(OR(K46=0,I46=0),"—",IF(K46>I46,"RENDIMIENTO SUPERIOR",IF(K46=I46,"MANTENIMIENTO","DEFICIT"))) -> — | M46: ='DAY 3'!M71 -> 0 | N46: =IF(OR(M46=0,K46=0),"—",IF(M46>K46,"RENDIMIENTO SUPERIOR",IF(M46=K46,"MANTENIMIENTO","DEFICIT"))) -> — | O46: ='DAY 3'!M84 -> 0 | P46: =IF(OR(O46=0,M46=0),"—",IF(O46>M46,"RENDIMIENTO SUPERIOR",IF(O46=M46,"MANTENIMIENTO","DEFICIT"))) -> — | Q46: ='DAY 3'!M97 -> 0 | R46: =IF(OR(Q46=0,O46=0),"—",IF(Q46>O46,"RENDIMIENTO SUPERIOR",IF(Q46=O46,"MANTENIMIENTO","DEFICIT"))) -> —
A47: DAY 3 | B47: Press inclinado en multipower | C47: ='DAY 3'!M7 -> 0 | D47: — | E47: ='DAY 3'!M20 -> 1550 | F47: =IF(OR(E47=0,C47=0),"—",IF(E47>C47,"RENDIMIENTO SUPERIOR",IF(E47=C47,"MANTENIMIENTO","DEFICIT"))) -> — | G47: ='DAY 3'!M33 -> 1200 | H47: =IF(OR(G47=0,E47=0),"—",IF(G47>E47,"RENDIMIENTO SUPERIOR",IF(G47=E47,"MANTENIMIENTO","DEFICIT"))) -> DEFICIT | I47: ='DAY 3'!M46 -> 1440 | J47: =IF(OR(I47=0,G47=0),"—",IF(I47>G47,"RENDIMIENTO SUPERIOR",IF(I47=G47,"MANTENIMIENTO","DEFICIT"))) -> RENDIMIENTO SUPERIOR | K47: ='DAY 3'!M59 -> 0 | L47: =IF(OR(K47=0,I47=0),"—",IF(K47>I47,"RENDIMIENTO SUPERIOR",IF(K47=I47,"MANTENIMIENTO","DEFICIT"))) -> — | M47: ='DAY 3'!M72 -> 0 | N47: =IF(OR(M47=0,K47=0),"—",IF(M47>K47,"RENDIMIENTO SUPERIOR",IF(M47=K47,"MANTENIMIENTO","DEFICIT"))) -> — | O47: ='DAY 3'!M85 -> 0 | P47: =IF(OR(O47=0,M47=0),"—",IF(O47>M47,"RENDIMIENTO SUPERIOR",IF(O47=M47,"MANTENIMIENTO","DEFICIT"))) -> — | Q47: ='DAY 3'!M98 -> 0 | R47: =IF(OR(Q47=0,O47=0),"—",IF(Q47>O47,"RENDIMIENTO SUPERIOR",IF(Q47=O47,"MANTENIMIENTO","DEFICIT"))) -> —
A48: DAY 3 | B48: Press declinado en maquina | C48: ='DAY 3'!M8 -> 0 | D48: — | E48: ='DAY 3'!M21 -> 1275 | F48: =IF(OR(E48=0,C48=0),"—",IF(E48>C48,"RENDIMIENTO SUPERIOR",IF(E48=C48,"MANTENIMIENTO","DEFICIT"))) -> — | G48: ='DAY 3'!M34 -> 1510 | H48: =IF(OR(G48=0,E48=0),"—",IF(G48>E48,"RENDIMIENTO SUPERIOR",IF(G48=E48,"MANTENIMIENTO","DEFICIT"))) -> RENDIMIENTO SUPERIOR | I48: ='DAY 3'!M47 -> 1600 | J48: =IF(OR(I48=0,G48=0),"—",IF(I48>G48,"RENDIMIENTO SUPERIOR",IF(I48=G48,"MANTENIMIENTO","DEFICIT"))) -> RENDIMIENTO SUPERIOR | K48: ='DAY 3'!M60 -> 0 | L48: =IF(OR(K48=0,I48=0),"—",IF(K48>I48,"RENDIMIENTO SUPERIOR",IF(K48=I48,"MANTENIMIENTO","DEFICIT"))) -> — | M48: ='DAY 3'!M73 -> 0 | N48: =IF(OR(M48=0,K48=0),"—",IF(M48>K48,"RENDIMIENTO SUPERIOR",IF(M48=K48,"MANTENIMIENTO","DEFICIT"))) -> — | O48: ='DAY 3'!M86 -> 0 | P48: =IF(OR(O48=0,M48=0),"—",IF(O48>M48,"RENDIMIENTO SUPERIOR",IF(O48=M48,"MANTENIMIENTO","DEFICIT"))) -> — | Q48: ='DAY 3'!M99 -> 0 | R48: =IF(OR(Q48=0,O48=0),"—",IF(Q48>O48,"RENDIMIENTO SUPERIOR",IF(Q48=O48,"MANTENIMIENTO","DEFICIT"))) -> —
A49: DAY 3 | B49: Aperturas en Pec-Deck | C49: ='DAY 3'!M9 -> 0 | D49: — | E49: ='DAY 3'!M22 -> 1530 | F49: =IF(OR(E49=0,C49=0),"—",IF(E49>C49,"RENDIMIENTO SUPERIOR",IF(E49=C49,"MANTENIMIENTO","DEFICIT"))) -> — | G49: ='DAY 3'!M35 -> 1530 | H49: =IF(OR(G49=0,E49=0),"—",IF(G49>E49,"RENDIMIENTO SUPERIOR",IF(G49=E49,"MANTENIMIENTO","DEFICIT"))) -> MANTENIMIENTO | I49: ='DAY 3'!M48 -> 1530 | J49: =IF(OR(I49=0,G49=0),"—",IF(I49>G49,"RENDIMIENTO SUPERIOR",IF(I49=G49,"MANTENIMIENTO","DEFICIT"))) -> MANTENIMIENTO | K49: ='DAY 3'!M61 -> 0 | L49: =IF(OR(K49=0,I49=0),"—",IF(K49>I49,"RENDIMIENTO SUPERIOR",IF(K49=I49,"MANTENIMIENTO","DEFICIT"))) -> — | M49: ='DAY 3'!M74 -> 0 | N49: =IF(OR(M49=0,K49=0),"—",IF(M49>K49,"RENDIMIENTO SUPERIOR",IF(M49=K49,"MANTENIMIENTO","DEFICIT"))) -> — | O49: ='DAY 3'!M87 -> 0 | P49: =IF(OR(O49=0,M49=0),"—",IF(O49>M49,"RENDIMIENTO SUPERIOR",IF(O49=M49,"MANTENIMIENTO","DEFICIT"))) -> — | Q49: ='DAY 3'!M100 -> 0 | R49: =IF(OR(Q49=0,O49=0),"—",IF(Q49>O49,"RENDIMIENTO SUPERIOR",IF(Q49=O49,"MANTENIMIENTO","DEFICIT"))) -> —
A50: DAY 3 | B50: Elevaciones laterales con mancuerna | C50: ='DAY 3'!M10 -> 0 | D50: — | E50: ='DAY 3'!M23 -> 405 | F50: =IF(OR(E50=0,C50=0),"—",IF(E50>C50,"RENDIMIENTO SUPERIOR",IF(E50=C50,"MANTENIMIENTO","DEFICIT"))) -> — | G50: ='DAY 3'!M36 -> 400 | H50: =IF(OR(G50=0,E50=0),"—",IF(G50>E50,"RENDIMIENTO SUPERIOR",IF(G50=E50,"MANTENIMIENTO","DEFICIT"))) -> DEFICIT | I50: ='DAY 3'!M49 -> 450 | J50: =IF(OR(I50=0,G50=0),"—",IF(I50>G50,"RENDIMIENTO SUPERIOR",IF(I50=G50,"MANTENIMIENTO","DEFICIT"))) -> RENDIMIENTO SUPERIOR | K50: ='DAY 3'!M62 -> 0 | L50: =IF(OR(K50=0,I50=0),"—",IF(K50>I50,"RENDIMIENTO SUPERIOR",IF(K50=I50,"MANTENIMIENTO","DEFICIT"))) -> — | M50: ='DAY 3'!M75 -> 0 | N50: =IF(OR(M50=0,K50=0),"—",IF(M50>K50,"RENDIMIENTO SUPERIOR",IF(M50=K50,"MANTENIMIENTO","DEFICIT"))) -> — | O50: ='DAY 3'!M88 -> 0 | P50: =IF(OR(O50=0,M50=0),"—",IF(O50>M50,"RENDIMIENTO SUPERIOR",IF(O50=M50,"MANTENIMIENTO","DEFICIT"))) -> — | Q50: ='DAY 3'!M101 -> 0 | R50: =IF(OR(Q50=0,O50=0),"—",IF(Q50>O50,"RENDIMIENTO SUPERIOR",IF(Q50=O50,"MANTENIMIENTO","DEFICIT"))) -> —
A51: DAY 3 | B51: Elevaciones laterales en polea baja | C51: ='DAY 3'!M11 -> 0 | D51: — | E51: ='DAY 3'!M24 -> 517.5 | F51: =IF(OR(E51=0,C51=0),"—",IF(E51>C51,"RENDIMIENTO SUPERIOR",IF(E51=C51,"MANTENIMIENTO","DEFICIT"))) -> — | G51: ='DAY 3'!M37 -> 562.5 | H51: =IF(OR(G51=0,E51=0),"—",IF(G51>E51,"RENDIMIENTO SUPERIOR",IF(G51=E51,"MANTENIMIENTO","DEFICIT"))) -> RENDIMIENTO SUPERIOR | I51: ='DAY 3'!M50 -> 562.5 | J51: =IF(OR(I51=0,G51=0),"—",IF(I51>G51,"RENDIMIENTO SUPERIOR",IF(I51=G51,"MANTENIMIENTO","DEFICIT"))) -> MANTENIMIENTO | K51: ='DAY 3'!M63 -> 0 | L51: =IF(OR(K51=0,I51=0),"—",IF(K51>I51,"RENDIMIENTO SUPERIOR",IF(K51=I51,"MANTENIMIENTO","DEFICIT"))) -> — | M51: ='DAY 3'!M76 -> 0 | N51: =IF(OR(M51=0,K51=0),"—",IF(M51>K51,"RENDIMIENTO SUPERIOR",IF(M51=K51,"MANTENIMIENTO","DEFICIT"))) -> — | O51: ='DAY 3'!M89 -> 0 | P51: =IF(OR(O51=0,M51=0),"—",IF(O51>M51,"RENDIMIENTO SUPERIOR",IF(O51=M51,"MANTENIMIENTO","DEFICIT"))) -> — | Q51: ='DAY 3'!M102 -> 0 | R51: =IF(OR(Q51=0,O51=0),"—",IF(Q51>O51,"RENDIMIENTO SUPERIOR",IF(Q51=O51,"MANTENIMIENTO","DEFICIT"))) -> —
A52: DAY 3 | B52: Elevaciones laterales en polea media | C52: ='DAY 3'!M12 -> 0 | D52: — | E52: ='DAY 3'!M25 -> 675 | F52: =IF(OR(E52=0,C52=0),"—",IF(E52>C52,"RENDIMIENTO SUPERIOR",IF(E52=C52,"MANTENIMIENTO","DEFICIT"))) -> — | G52: ='DAY 3'!M38 -> 900 | H52: =IF(OR(G52=0,E52=0),"—",IF(G52>E52,"RENDIMIENTO SUPERIOR",IF(G52=E52,"MANTENIMIENTO","DEFICIT"))) -> RENDIMIENTO SUPERIOR | I52: ='DAY 3'!M51 -> 900 | J52: =IF(OR(I52=0,G52=0),"—",IF(I52>G52,"RENDIMIENTO SUPERIOR",IF(I52=G52,"MANTENIMIENTO","DEFICIT"))) -> MANTENIMIENTO | K52: ='DAY 3'!M64 -> 0 | L52: =IF(OR(K52=0,I52=0),"—",IF(K52>I52,"RENDIMIENTO SUPERIOR",IF(K52=I52,"MANTENIMIENTO","DEFICIT"))) -> — | M52: ='DAY 3'!M77 -> 0 | N52: =IF(OR(M52=0,K52=0),"—",IF(M52>K52,"RENDIMIENTO SUPERIOR",IF(M52=K52,"MANTENIMIENTO","DEFICIT"))) -> — | O52: ='DAY 3'!M90 -> 0 | P52: =IF(OR(O52=0,M52=0),"—",IF(O52>M52,"RENDIMIENTO SUPERIOR",IF(O52=M52,"MANTENIMIENTO","DEFICIT"))) -> — | Q52: ='DAY 3'!M103 -> 0 | R52: =IF(OR(Q52=0,O52=0),"—",IF(Q52>O52,"RENDIMIENTO SUPERIOR",IF(Q52=O52,"MANTENIMIENTO","DEFICIT"))) -> —
A53: DAY 3 | B53: Extension de triceps en polea alta | C53: ='DAY 3'!M13 -> 0 | D53: — | E53: ='DAY 3'!M26 -> 760 | F53: =IF(OR(E53=0,C53=0),"—",IF(E53>C53,"RENDIMIENTO SUPERIOR",IF(E53=C53,"MANTENIMIENTO","DEFICIT"))) -> — | G53: ='DAY 3'!M39 -> 900 | H53: =IF(OR(G53=0,E53=0),"—",IF(G53>E53,"RENDIMIENTO SUPERIOR",IF(G53=E53,"MANTENIMIENTO","DEFICIT"))) -> RENDIMIENTO SUPERIOR | I53: ='DAY 3'!M52 -> 900 | J53: =IF(OR(I53=0,G53=0),"—",IF(I53>G53,"RENDIMIENTO SUPERIOR",IF(I53=G53,"MANTENIMIENTO","DEFICIT"))) -> MANTENIMIENTO | K53: ='DAY 3'!M65 -> 0 | L53: =IF(OR(K53=0,I53=0),"—",IF(K53>I53,"RENDIMIENTO SUPERIOR",IF(K53=I53,"MANTENIMIENTO","DEFICIT"))) -> — | M53: ='DAY 3'!M78 -> 0 | N53: =IF(OR(M53=0,K53=0),"—",IF(M53>K53,"RENDIMIENTO SUPERIOR",IF(M53=K53,"MANTENIMIENTO","DEFICIT"))) -> — | O53: ='DAY 3'!M91 -> 0 | P53: =IF(OR(O53=0,M53=0),"—",IF(O53>M53,"RENDIMIENTO SUPERIOR",IF(O53=M53,"MANTENIMIENTO","DEFICIT"))) -> — | Q53: ='DAY 3'!M104 -> 0 | R53: =IF(OR(Q53=0,O53=0),"—",IF(Q53>O53,"RENDIMIENTO SUPERIOR",IF(Q53=O53,"MANTENIMIENTO","DEFICIT"))) -> —
A54: DAY 3 | B54: Extensiones Katana en polea | C54: ='DAY 3'!M14 -> 0 | D54: — | E54: ='DAY 3'!M27 -> 480 | F54: =IF(OR(E54=0,C54=0),"—",IF(E54>C54,"RENDIMIENTO SUPERIOR",IF(E54=C54,"MANTENIMIENTO","DEFICIT"))) -> — | G54: ='DAY 3'!M40 -> 540 | H54: =IF(OR(G54=0,E54=0),"—",IF(G54>E54,"RENDIMIENTO SUPERIOR",IF(G54=E54,"MANTENIMIENTO","DEFICIT"))) -> RENDIMIENTO SUPERIOR | I54: ='DAY 3'!M53 -> 540 | J54: =IF(OR(I54=0,G54=0),"—",IF(I54>G54,"RENDIMIENTO SUPERIOR",IF(I54=G54,"MANTENIMIENTO","DEFICIT"))) -> MANTENIMIENTO | K54: ='DAY 3'!M66 -> 0 | L54: =IF(OR(K54=0,I54=0),"—",IF(K54>I54,"RENDIMIENTO SUPERIOR",IF(K54=I54,"MANTENIMIENTO","DEFICIT"))) -> — | M54: ='DAY 3'!M79 -> 0 | N54: =IF(OR(M54=0,K54=0),"—",IF(M54>K54,"RENDIMIENTO SUPERIOR",IF(M54=K54,"MANTENIMIENTO","DEFICIT"))) -> — | O54: ='DAY 3'!M92 -> 0 | P54: =IF(OR(O54=0,M54=0),"—",IF(O54>M54,"RENDIMIENTO SUPERIOR",IF(O54=M54,"MANTENIMIENTO","DEFICIT"))) -> — | Q54: ='DAY 3'!M105 -> 0 | R54: =IF(OR(Q54=0,O54=0),"—",IF(Q54>O54,"RENDIMIENTO SUPERIOR",IF(Q54=O54,"MANTENIMIENTO","DEFICIT"))) -> —
...

Sheet TRACKER
A1: TRACKER DIARIO — SEGUIMIENTO DE METRICAS CORPORALES Y NUTRICION
A2: Registro Diario | Promedios Semanales | Delta Peso | BF% Automatico
A3: PARAMETROS DE REFERENCIA (solo modificar si cambias el punto de partida)
A4: PESO INICIAL (kg) | B4: 53.7 | C4: BF% INICIAL | D4: 12 | E4: FECHA INICIO | F4: 25/03/2026
A6: FECHA | B6: PESO AYUNAS (kg) [ ] | C6: KCAL Consumidas [ ] | D6: PROTEINA (g) [ ] | E6: CARBOS (g) [ ] | F6: GRASA (g) [ ] | G6: PASOS Diarios [ ] | H6: SUENO (h) [ ] | I6: BF% Estimado (Auto-Calculado) | J6: NOTAS
A7: Wed 25/03/2026 | B7: 53.7 | C7: 1.353 | D7: 124.1 | E7: 130.5 | F7: 26.6 | G7: 10.416 | H7: 7 | I7: =IF(B7="","",ROUND($D$4-(($B$4-B7)/$B$4)*100,1)) -> 12
A8: Thu 26/03/2026 | B8: 53.3 | C8: 1.865 | D8: 143.5 | E8: 237 | F8: 36.6 | G8: 11.51 | H8: 7 | I8: =IF(B8="","",ROUND($D$4-(($B$4-B8)/$B$4)*100,1)) -> 11.3
A9: Fri 27/03/2026 | B9: 53.9 | C9: 1.832 | D9: 142.5 | E9: 229.3 | F9: 20.8 | G9: 11.51 | H9: 7 | I9: =IF(B9="","",ROUND($D$4-(($B$4-B9)/$B$4)*100,1)) -> 12.4
A10: Sat 28/03/2026 | B10: 54 | C10: 1.481 | D10: 121.6 | E10: 162.2 | F10: 30.1 | G10: ? | H10: 8 | I10: =IF(B10="","",ROUND($D$4-(($B$4-B10)/$B$4)*100,1)) -> 12.6 | J10: Res day
A11: Promedio S0 Arranque | B11: =IFERROR(AVERAGE(B7,B8,B9,B10),"") -> 53.725 | C11: =IFERROR(AVERAGE(C7,C8,C9,C10),"") -> 1.63275 | D11: =IFERROR(AVERAGE(D7,D8,D9,D10),"") -> 132.925 | E11: =IFERROR(AVERAGE(E7,E8,E9,E10),"") -> 189.75 | F11: =IFERROR(AVERAGE(F7,F8,F9,F10),"") -> 28.525 | G11: =IFERROR(AVERAGE(G7,G8,G9,G10),"") -> 11.145333 | H11: =IFERROR(AVERAGE(H7,H8,H9,H10),"") -> 7.25 | I11: =IFERROR(AVERAGE(I7,I8,I9,I10),"") -> 12.075
A13: Sun 29/03/2026 | B13: 53.8 | C13: 1.631 | D13: 124.4 | E13: 213.8 | F13: 30.2 | G13: 6.319 | H13: 7 | I13: =IF(B13="","",ROUND($D$4-(($B$4-B13)/$B$4)*100,1)) -> 12.2
A14: Mon 30/03/2026 | B14: 52.9 | C14: 1.669 | D14: 136.1 | E14: 192.8 | F14: 29.4 | G14: 12.425 | H14: 10 | I14: =IF(B14="","",ROUND($D$4-(($B$4-B14)/$B$4)*100,1)) -> 10.5
A15: Tue 31/03/2026 | B15: 52.6 | C15: 1.655 | D15: 132.8 | E15: 193.4 | F15: 33.5 | G15: 6.667 | H15: 8 | I15: =IF(B15="","",ROUND($D$4-(($B$4-B15)/$B$4)*100,1)) -> 10
A16: Wed 01/04/2026 | B16: 52 | C16: 1.867 | D16: 125.2 | E16: 137.6 | F16: 35.8 | G16: 12.433 | H16: 8 | I16: =IF(B16="","",ROUND($D$4-(($B$4-B16)/$B$4)*100,1)) -> 8.8
A17: Thu 02/04/2026 | B17: 52.7 | C17: 1.601 | D17: 173.9 | E17: 162.1 | F17: 25.7 | G17: 8.827 | H17: 10 | I17: =IF(B17="","",ROUND($D$4-(($B$4-B17)/$B$4)*100,1)) -> 10.1
A18: Fri 03/04/2026 | B18: 53.2 | C18: 1.421 | D18: 121.7 | E18: 169.1 | F18: 21.9 | G18: 4.649 | H18: 8 | I18: =IF(B18="","",ROUND($D$4-(($B$4-B18)/$B$4)*100,1)) -> 11.1
A19: Sat 04/04/2026 | B19: 52.7 | C19: 1.603 | D19: 126.1 | E19: 172.3 | F19: 25.9 | G19: 7.953 | H19: 6 | I19: =IF(B19="","",ROUND($D$4-(($B$4-B19)/$B$4)*100,1)) -> 10.1
A20: Promedio MC01 | B20: =IFERROR(AVERAGE(B13,B14,B15,B16,B17,B18,B19),"") -> 52.842857 | C20: =IFERROR(AVERAGE(C13,C14,C15,C16,C17,C18,C19),"") -> 1.6352857 | D20: =IFERROR(AVERAGE(D13,D14,D15,D16,D17,D18,D19),"") -> 134.31429 | E20: =IFERROR(AVERAGE(E13,E14,E15,E16,E17,E18,E19),"") -> 177.3 | F20: =IFERROR(AVERAGE(F13,F14,F15,F16,F17,F18,F19),"") -> 28.914286 | G20: =IFERROR(AVERAGE(G13,G14,G15,G16,G17,G18,G19),"") -> 8.4675714 | H20: =IFERROR(AVERAGE(H13,H14,H15,H16,H17,H18,H19),"") -> 8.1428571 | I20: =IFERROR(AVERAGE(I13,I14,I15,I16,I17,I18,I19),"") -> 10.4
A21: Delta Peso vs Semana Anterior | B21: =IFERROR(B20-B11,"") -> -0.88214286
A23: Sun 05/04/2026 | B23: 53.2 | C23: 1.864 | D23: 132.2 | E23: 211.0 | F23: 37.9 | G23: 5.907 | H23: 6 | I23: =IF(B23="","",ROUND($D$4-(($B$4-B23)/$B$4)*100,1)) -> 11.1
A24: Mon 06/04/2026 | B24: 53.4 | C24: 1.773 | D24: 122.5 | E24: 165.3 | F24: 35.5 | G24: 6.772 | H24: 6 | I24: =IF(B24="","",ROUND($D$4-(($B$4-B24)/$B$4)*100,1)) -> 11.4
A25: Tue 07/04/2026 | B25: 53.3 | C25: 1.886 | D25: 134.6 | E25: 250.4 | F25: 34.6 | G25: 16.689 | H25: 3.59 | I25: =IF(B25="","",ROUND($D$4-(($B$4-B25)/$B$4)*100,1)) -> 11.3 | J25: Registro con reloj
A26: Wed 08/04/2026 | B26: 52.8 | C26: 1.689 | D26: 116.7 | E26: 212.1 | F26: 50.2 | G26: 14.624 | H26: 7.11 | I26: =IF(B26="","",ROUND($D$4-(($B$4-B26)/$B$4)*100,1)) -> 10.3 | J26: Cumple Laia (Comida en restaurante)
A27: Thu 09/04/2026 | B27: 53.2 | C27: 1.758 | D27: 145 | E27: 170 | F27: 29 | G27: 15.977 | H27: 6.52 | I27: =IF(B27="","",ROUND($D$4-(($B$4-B27)/$B$4)*100,1)) -> 11.1
A28: Fri 10/04/2026 | B28: 52.9 | C28: 1.375 | D28: 132 | E28: 114.8 | F28: 35.1 | G28: 9050 | H28: 7.32 | I28: =IF(B28="","",ROUND($D$4-(($B$4-B28)/$B$4)*100,1)) -> 10.5
A29: Sat 11/04/2026 | B29: 53.3 | C29: 1.836 | D29: 141.5 | E29: 253 | F29: 29.3 | G29: 14.982 | H29: 7.12 | I29: =IF(B29="","",ROUND($D$4-(($B$4-B29)/$B$4)*100,1)) -> 11.3
A30: Promedio MC02 | B30: =IFERROR(AVERAGE(B23,B24,B25,B26,B27,B28,B29),"") -> 53.157143 | C30: =IFERROR(AVERAGE(C23,C24,C25,C26,C27,C28,C29),"") -> 1.7401429 | D30: =IFERROR(AVERAGE(D23,D24,D25,D26,D27,D28,D29),"") -> 132.07143 | E30: =IFERROR(AVERAGE(E23,E24,E25,E26,E27,E28,E29),"") -> 194.26667 | F30: =IFERROR(AVERAGE(F23,F24,F25,F26,F27,F28,F29),"") -> 35.942857 | G30: =IFERROR(AVERAGE(G23,G24,G25,G26,G27,G28,G29),"") -> 1303.5644 | H30: =IFERROR(AVERAGE(H23,H24,H25,H26,H27,H28,H29),"") -> 6.2371429 | I30: =IFERROR(AVERAGE(I23,I24,I25,I26,I27,I28,I29),"") -> 11
A31: Delta Peso vs Semana Anterior | B31: =IFERROR(B30-B20,"") -> 0.31428571
A33: Sun 12/04/2026 | B33: 53.3 | C33: 1.475 | D33: 138.7 | E33: 169.4 | F33: 12.9 | G33: 10.767 | H33: 7.12 | I33: =IF(B33="","",ROUND($D$4-(($B$4-B33)/$B$4)*100,1)) -> 11.3
A34: Mon 13/04/2026 | B34: 53.4 | C34: 1.361 | D34: 125 | E34: 147.7 | F34: 17.9 | G34: 14.982 | H34: 7.48 | I34: =IF(B34="","",ROUND($D$4-(($B$4-B34)/$B$4)*100,1)) -> 11.4
A35: Tue 14/04/2026 | B35: 53 | C35: 1.398 | D35: 117.1 | E35: 146.9 | F35: 34.2 | G35: 16.791 | H35: 6.5 | I35: =IF(B35="","",ROUND($D$4-(($B$4-B35)/$B$4)*100,1)) -> 10.7
A36: Wed 15/04/2026 | B36: 52.8 | C36: 1657 | D36: 164.5 | E36: 178.5 | F36: 36.4 | G36: 14.303 | H36: 6.58 | I36: =IF(B36="","",ROUND($D$4-(($B$4-B36)/$B$4)*100,1)) -> 10.3
A37: Thu 16/04/2026 | B37: 52.8 | C37: 1355 | D37: 121.7 | E37: 167.4 | F37: 16.8 | I37: =IF(B37="","",ROUND(C26-(($B$4-B37)/$B$4)*100,1)) -> 0
A38: Fri 17/04/2026 | B38: 52.8 | C38: 1450 | D38: 140 | E38: 125 | F38: 30 | I38: =IF(B38="","",ROUND($D$4-(($B$4-B38)/$B$4)*100,1)) -> 10.3
A39: Sat 18/04/2026 | B39: 52.8 | C39: 1140 | D39: 111 | E39: 91.4 | F39: 34.8 | I39: =IF(B39="","",ROUND($D$4-(($B$4-B39)/$B$4)*100,1)) -> 10.3
A40: Promedio MC03 | B40: =IFERROR(AVERAGE(B33,B34,B35,B36,B37,B38,B39),"") -> 52.985714 | C40: =IFERROR(AVERAGE(C33,C34,C35,C36,C37,C38,C39),"") -> 800.89057 | D40: =IFERROR(AVERAGE(D33,D34,D35,D36,D37,D38,D39),"") -> 131.14286 | E40: =IFERROR(AVERAGE(E33,E34,E35,E36,E37,E38,E39),"") -> 146.61429 | F40: =IFERROR(AVERAGE(F33,F34,F35,F36,F37,F38,F39),"") -> 26.142857 | G40: =IFERROR(AVERAGE(G33,G34,G35,G36,G37,G38,G39),"") -> 14.21075 | H40: =IFERROR(AVERAGE(H33,H34,H35,H36,H37,H38,H39),"") -> 6.92 | I40: =IFERROR(AVERAGE(I33,I34,I35,I36,I37,I38,I39),"") -> 9.1857143
A41: Delta Peso vs Semana Anterior | B41: =IFERROR(B40-B30,"") -> -0.17142857
A43: Sun 19/04/2026 | B43: 52.8 | C43: 1.783 | D43: 123.5 | E43: 201.6 | F43: 26.4 | I43: =IF(B43="","",ROUND($D$4-(($B$4-B43)/$B$4)*100,1)) -> 10.3
A44: Mon 20/04/2026 | B44: 53.3 | C44: 1.938 | D44: 147.1 | E44: 245.5 | F44: 31.8 | I44: =IF(B44="","",ROUND($D$4-(($B$4-B44)/$B$4)*100,1)) -> 11.3
A45: Tue 21/04/2026 | B45: 53.4 | I45: =IF(B45="","",ROUND($D$4-(($B$4-B45)/$B$4)*100,1)) -> 11.4
...

Sheet DAY 1
A1: DAY 1 — DOMINGO — Pierna + Hombro + Core
A2: CALENTAMIENTO (5-8 min)
A3: [ ] Balanceos Pierna | B3: [ ] Rot. Ext. Hombro | F3: [ ] Band Pull-aparts
A4: EJERCICIO | B4: MC | C4: REPS OBJETIVO + RP | D4: RIR S1 | E4: Reps S1 | F4: Kg S1 | G4: RIR S2 | H4: Reps S2 | I4: Kg S2 | J4: RIR S3 | K4: Reps S3 | L4: Kg S3 | M4: TONELAJE (Auto) | N4: COSAS A COMENTAR | O4: HECHO [ ]
A5: MICROCICLO 01
A6: Zancadas con mancuernas | B6: MC01 | C6: 10-12 | D6: 1 | E6: 0 | F6: 0 | G6: 1 | H6: 0 | I6: 0 | J6: 1 | K6: 0 | L6: 0 | M6: =IFERROR(IFERROR(E6*F6,0)+IFERROR(H6*I6,0)+IFERROR(K6*L6,0),0) -> 0
A7: Extension de cuadriceps en maquina | B7: MC01 | C7: 12-15 + DS | D7: 2 | E7: 0 | F7: 0 | G7: 1 | H7: 0 | I7: 0 | J7: 0 | K7: 0 | L7: 0 | M7: =IFERROR(IFERROR(E7*F7,0)+IFERROR(H7*I7,0)+IFERROR(K7*L7,0),0) -> 0
A8: Curl femoral tumbado en maquina | B8: MC01 | C8: 12-15 + DS | D8: 2 | E8: 0 | F8: 0 | G8: 1 | H8: 0 | I8: 0 | J8: 0 | K8: 0 | L8: 0 | M8: =IFERROR(IFERROR(E8*F8,0)+IFERROR(H8*I8,0)+IFERROR(K8*L8,0),0) -> 0
A9: Elevaciones laterales con mancuerna | B9: MC01 | C9: 15-20 | D9: 0 | E9: 0 | F9: 0 | G9: 0 | H9: 0 | I9: 0 | J9: 0 | K9: 0 | L9: 0 | M9: =IFERROR(IFERROR(E9*F9,0)+IFERROR(H9*I9,0)+IFERROR(K9*L9,0),0) -> 0
A10: Elevaciones laterales en polea baja | B10: MC01 | C10: 15-20 | D10: 0 | E10: 0 | F10: 0 | G10: 0 | H10: 0 | I10: 0 | J10: 0 | K10: 0 | L10: 0 | M10: =IFERROR(IFERROR(E10*F10,0)+IFERROR(H10*I10,0)+IFERROR(K10*L10,0),0) -> 0
A11: Elevaciones laterales en polea media | B11: MC01 | C11: 15-20 | D11: 0 | E11: 0 | F11: 0 | G11: 0 | H11: 0 | I11: 0 | J11: 0 | K11: 0 | L11: 0 | M11: =IFERROR(IFERROR(E11*F11,0)+IFERROR(H11*I11,0)+IFERROR(K11*L11,0),0) -> 0
A12: Crunch abdominal en polea | B12: MC01 | C12: 15-20 + Fallo | D12: 0 | E12: 0 | F12: 0 | G12: 0 | H12: 0 | I12: 0 | J12: 0 | K12: 0 | L12: 0 | M12: =IFERROR(IFERROR(E12*F12,0)+IFERROR(H12*I12,0)+IFERROR(K12*L12,0),0) -> 0
A13: TONELAJE TOTAL MC01 | M13: =SUM(M6,M7,M8,M9,M10,M11,M12) -> 0
A15: MICROCICLO 02
A16: Zancadas con mancuernas | B16: MC02 | C16: 10-12 | D16: 1 | E16: 12 | F16: 15 | G16: 1 | H16: 12 | I16: 15 | J16: 1 | K16: 12 | L16: 15 | M16: =IFERROR(IFERROR(E16*F16,0)+IFERROR(H16*I16,0)+IFERROR(K16*L16,0),0) -> 540
A17: Extension de cuadriceps en maquina | B17: MC02 | C17: 12-15 + DS | D17: 2 | E17: 12 | F17: 42.5 | G17: 1 | H17: 12 | I17: 50 | J17: 0 | K17: 12 | L17: 42.5 | M17: =IFERROR(IFERROR(E17*F17,0)+IFERROR(H17*I17,0)+IFERROR(K17*L17,0),0) -> 1620
A18: Curl femoral tumbado en maquina | B18: MC02 | C18: 12-15 + DS | D18: 2 | E18: 10 | F18: 22.5 | G18: 1 | H18: 10 | I18: 22.5 | J18: 0 | K18: 10 | L18: 22.5 | M18: =IFERROR(IFERROR(E18*F18,0)+IFERROR(H18*I18,0)+IFERROR(K18*L18,0),0) -> 675
A19: Elevaciones laterales con mancuerna | B19: MC02 | C19: 15-20 | D19: 0 | E19: 15 | F19: 8 | G19: 0 | H19: 15 | I19: 8 | J19: 0 | K19: 15 | L19: 8 | M19: =IFERROR(IFERROR(E19*F19,0)+IFERROR(H19*I19,0)+IFERROR(K19*L19,0),0) -> 360
A20: Elevaciones laterales en polea baja | B20: MC02 | C20: 15-20 | D20: 0 | E20: 15 | F20: 11.5 | G20: 0 | H20: 15 | I20: 11.5 | J20: 0 | K20: 15 | L20: 11.5 | M20: =IFERROR(IFERROR(E20*F20,0)+IFERROR(H20*I20,0)+IFERROR(K20*L20,0),0) -> 517.5
A21: Elevaciones laterales en polea media | B21: MC02 | C21: 15-20 | D21: 0 | E21: 15 | F21: 15 | G21: 0 | H21: 15 | I21: 15 | J21: 0 | K21: 15 | L21: 15 | M21: =IFERROR(IFERROR(E21*F21,0)+IFERROR(H21*I21,0)+IFERROR(K21*L21,0),0) -> 675
A22: Crunch abdominal en polea | B22: MC02 | C22: 15-20 + Fallo | D22: 0 | E22: 18 | F22: 57.5 | G22: 0 | H22: 16 | I22: 57.5 | J22: 0 | K22: 17 | L22: 57.5 | M22: =IFERROR(IFERROR(E22*F22,0)+IFERROR(H22*I22,0)+IFERROR(K22*L22,0),0) -> 2932.5
A23: TONELAJE TOTAL MC02 | M23: =SUM(M16,M17,M18,M19,M20,M21,M22) -> 7320
A25: MICROCICLO 03
A26: Zancadas con mancuernas | B26: MC03 | C26: 10-12 | D26: 1 | E26: 12 | F26: 15 | G26: 1 | H26: 12 | I26: 15 | J26: 1 | K26: 12 | L26: 15 | M26: =IFERROR(IFERROR(E26*F26,0)+IFERROR(H26*I26,0)+IFERROR(K26*L26,0),0) -> 540
A27: Extension de cuadriceps en maquina | B27: MC03 | C27: 12-15 + DS | D27: 2 | E27: 12 | F27: 57.5 | G27: 1 | H27: 12 | I27: 57.5 | J27: 0 | K27: 13 | L27: 57.5 | M27: =IFERROR(IFERROR(E27*F27,0)+IFERROR(H27*I27,0)+IFERROR(K27*L27,0),0) -> 2127.5
A28: Curl femoral tumbado en maquina | B28: MC03 | C28: 12-15 + DS | D28: 2 | E28: 10 | F28: 22.5 | G28: 1 | H28: 10 | I28: 22.5 | J28: 0 | K28: 10 | L28: 22.5 | M28: =IFERROR(IFERROR(E28*F28,0)+IFERROR(H28*I28,0)+IFERROR(K28*L28,0),0) -> 675
A29: Elevaciones laterales con mancuerna | B29: MC03 | C29: 15-20 | D29: 0 | E29: 18 | F29: 9 | G29: 0 | H29: 16 | I29: 9 | J29: 0 | K29: 16 | L29: 9 | M29: =IFERROR(IFERROR(E29*F29,0)+IFERROR(H29*I29,0)+IFERROR(K29*L29,0),0) -> 450
A30: Elevaciones laterales en polea baja | B30: MC03 | C30: 15-20 | D30: 0 | E30: 15 | F30: 11.5 | G30: 0 | H30: 15 | I30: 15 | J30: 0 | K30: 15 | L30: 15 | M30: =IFERROR(IFERROR(E30*F30,0)+IFERROR(H30*I30,0)+IFERROR(K30*L30,0),0) -> 622.5
A31: Elevaciones laterales en polea media | B31: MC03 | C31: 15-20 | D31: 0 | E31: 12 | F31: 20 | G31: 0 | H31: 13 | I31: 17.5 | J31: 0 | K31: 12 | L31: 17.5 | M31: =IFERROR(IFERROR(E31*F31,0)+IFERROR(H31*I31,0)+IFERROR(K31*L31,0),0) -> 677.5
A32: Crunch abdominal en polea | B32: MC03 | C32: 15-20 + Fallo | D32: 0 | E32: 16 | F32: 57.5 | G32: 0 | H32: 16 | I32: 57.5 | J32: 0 | K32: 14 | L32: 57.5 | M32: =IFERROR(IFERROR(E32*F32,0)+IFERROR(H32*I32,0)+IFERROR(K32*L32,0),0) -> 2645
A33: TONELAJE TOTAL MC03 | M33: =SUM(M26,M27,M28,M29,M30,M31,M32) -> 7737.5
A35: MICROCICLO 04
A36: Zancadas con mancuernas | B36: MC04 | C36: 10-12 | D36: 1 | E36: 12 | F36: 15 | G36: 1 | H36: 12 | I36: 15 | J36: 1 | K36: 12 | L36: 15 | M36: =IFERROR(IFERROR(E36*F36,0)+IFERROR(H36*I36,0)+IFERROR(K36*L36,0),0) -> 540
A37: Extension de cuadriceps en maquina | B37: MC04 | C37: 12-15 + DS | D37: 2 | E37: 12 | F37: 57.5 | G37: 1 | H37: 12 | I37: 57.5 | J37: 0 | K37: 12 | L37: 62.5 | M37: =IFERROR(IFERROR(E37*F37,0)+IFERROR(H37*I37,0)+IFERROR(K37*L37,0),0) -> 2130
A38: Curl femoral tumbado en maquina | B38: MC04 | C38: 12-15 + DS | D38: 2 | E38: 10 | F38: 22.5 | G38: 1 | H38: 10 | I38: 22.5 | J38: 0 | K38: 10 | L38: 22.5 | M38: =IFERROR(IFERROR(E38*F38,0)+IFERROR(H38*I38,0)+IFERROR(K38*L38,0),0) -> 675
A39: Elevaciones laterales con mancuerna | B39: MC04 | C39: 15-20 | D39: 0 | E39: 15 | F39: 10 | G39: 0 | H39: 15 | I39: 10 | J39: 0 | K39: 15 | L39: 10 | M39: =IFERROR(IFERROR(E39*F39,0)+IFERROR(H39*I39,0)+IFERROR(K39*L39,0),0) -> 450
A40: Elevaciones laterales en polea baja | B40: MC04 | C40: 15-20 | D40: 0 | E40: 15 | F40: 11.5 | G40: 0 | H40: 15 | I40: 11.5 | J40: 0 | K40: 15 | L40: 11.5 | M40: =IFERROR(IFERROR(E40*F40,0)+IFERROR(H40*I40,0)+IFERROR(K40*L40,0),0) -> 517.5
A41: Elevaciones laterales en polea media | B41: MC04 | C41: 15-20 | D41: 0 | E41: 15 | F41: 17.5 | G41: 0 | H41: 15 | I41: 17.5 | J41: 0 | K41: 15 | L41: 15 | M41: =IFERROR(IFERROR(E41*F41,0)+IFERROR(H41*I41,0)+IFERROR(K41*L41,0),0) -> 750
A42: Crunch abdominal en polea | B42: MC04 | C42: 15-20 + Fallo | D42: 0 | E42: 16 | F42: 57.5 | G42: 0 | H42: 16 | I42: 57.5 | J42: 0 | K42: 16 | L42: 57.5 | M42: =IFERROR(IFERROR(E42*F42,0)+IFERROR(H42*I42,0)+IFERROR(K42*L42,0),0) -> 2760
A43: TONELAJE TOTAL MC04 | M43: =SUM(M36,M37,M38,M39,M40,M41,M42) -> 7822.5
...

Sheet DAY 2
A1: 0
A2: CALENTAMIENTO (5-8 min)
A3: [ ] Activacion Escapular | B3: [ ] Face-pull Ligero | F3: [ ] Circulos Hombros
A4: EJERCICIO | B4: MC | C4: REPS OBJETIVO + RP | D4: RIR S1 | E4: Reps S1 | F4: Kg S1 | G4: RIR S2 | H4: Reps S2 | I4: Kg S2 | J4: RIR S3 | K4: Reps S3 | L4: Kg S3 | M4: TONELAJE (Auto) | N4: COSAS A COMENTAR | O4: HECHO [ ]
A5: MICROCICLO 01
A6: Jalon al pecho con agarre neutro | B6: MC01 | C6: 10-12 | D6: 1 | E6: 0 | F6: 0 | G6: 1 | H6: 0 | I6: 0 | J6: 1 | K6: 0 | L6: 0 | M6: =IFERROR(IFERROR(E6*F6,0)+IFERROR(H6*I6,0)+IFERROR(K6*L6,0),0) -> 0
A7: Remo en maquina con apoyo en el pecho | B7: MC01 | C7: 10-12 | D7: 1 | E7: 0 | F7: 0 | G7: 1 | H7: 0 | I7: 0 | J7: 1 | K7: 0 | L7: 0 | M7: =IFERROR(IFERROR(E7*F7,0)+IFERROR(H7*I7,0)+IFERROR(K7*L7,0),0) -> 0
A8: Remo Gironda en polea baja | B8: MC01 | C8: 12-15 + RP | D8: 1 | E8: 0 | F8: 0 | G8: 1 | H8: 0 | I8: 0 | J8: 0 | K8: 0 | L8: 0 | M8: =IFERROR(IFERROR(E8*F8,0)+IFERROR(H8*I8,0)+IFERROR(K8*L8,0),0) -> 0
A9: Pull-over con cuerda en polea alta | B9: MC01 | C9: 12-15 | D9: 0 | E9: 0 | F9: 0 | G9: 0 | H9: 0 | I9: 0 | J9: 0 | K9: 0 | L9: 0 | M9: =IFERROR(IFERROR(E9*F9,0)+IFERROR(H9*I9,0)+IFERROR(K9*L9,0),0) -> 0
A10: Pajaros para deltoide posterior en maquina | B10: MC01 | C10: 15-20 + DS | D10: 1 | E10: 0 | F10: 0 | G10: 0 | H10: 0 | I10: 0 | J10: 0 | K10: 0 | L10: 0 | M10: =IFERROR(IFERROR(E10*F10,0)+IFERROR(H10*I10,0)+IFERROR(K10*L10,0),0) -> 0
A11: Curl Scott en maquina | B11: MC01 | C11: 10-12 + Fallo | D11: 0 | E11: 0 | F11: 0 | G11: 0 | H11: 0 | I11: 0 | J11: 0 | K11: 0 | L11: 0 | M11: =IFERROR(IFERROR(E11*F11,0)+IFERROR(H11*I11,0)+IFERROR(K11*L11,0),0) -> 0
A12: Rueda abdominal | B12: MC01 | C12: 10-15 + Fallo | D12: 0 | E12: 0 | F12: 0 | G12: 0 | H12: 0 | I12: 0 | J12: 0 | K12: 0 | L12: 0 | M12: =IFERROR(IFERROR(E12*F12,0)+IFERROR(H12*I12,0)+IFERROR(K12*L12,0),0) -> 0
A13: TONELAJE TOTAL MC01 | M13: =SUM(M6,M7,M8,M9,M10,M11,M12) -> 0
A15: MICROCICLO 02
A16: Jalon al pecho con agarre neutro | B16: MC02 | C16: 10-12 | D16: 1 | E16: 12 | F16: 70 | G16: 1 | H16: 10 | I16: 80 | J16: 1 | K16: 10 | L16: 70 | M16: =IFERROR(IFERROR(E16*F16,0)+IFERROR(H16*I16,0)+IFERROR(K16*L16,0),0) -> 2340
A17: Remo en maquina con apoyo en el pecho | B17: MC02 | C17: 10-12 | D17: 1 | E17: 10 | F17: 60 | G17: 1 | H17: 10 | I17: 60 | J17: 1 | K17: 10 | L17: 60 | M17: =IFERROR(IFERROR(E17*F17,0)+IFERROR(H17*I17,0)+IFERROR(K17*L17,0),0) -> 1800
A18: Remo Gironda en polea baja | B18: MC02 | C18: 12-15 + RP | D18: 1 | E18: 10 | F18: 70 | G18: 1 | H18: 10 | I18: 80 | J18: 0 | K18: 10 | L18: 70 | M18: =IFERROR(IFERROR(E18*F18,0)+IFERROR(H18*I18,0)+IFERROR(K18*L18,0),0) -> 2200
A19: Pull-over con cuerda en polea alta | B19: MC02 | C19: 12-15 | D19: 0 | E19: 12 | F19: 30 | G19: 0 | H19: 12 | I19: 30 | J19: 0 | K19: 12 | L19: 30 | M19: =IFERROR(IFERROR(E19*F19,0)+IFERROR(H19*I19,0)+IFERROR(K19*L19,0),0) -> 1080
A20: Pajaros para deltoide posterior en maquina | B20: MC02 | C20: 15-20 + DS | D20: 1 | E20: 10 | F20: 35 | G20: 0 | H20: 10 | I20: 35 | J20: 0 | K20: 10 | L20: 35 | M20: =IFERROR(IFERROR(E20*F20,0)+IFERROR(H20*I20,0)+IFERROR(K20*L20,0),0) -> 1050
A21: Curl Scott en maquina | B21: MC02 | C21: 10-12 + Fallo | D21: 0 | E21: 12 | F21: 15 | G21: 0 | H21: 12 | I21: 15 | J21: 0 | K21: 12 | L21: 15 | M21: =IFERROR(IFERROR(E21*F21,0)+IFERROR(H21*I21,0)+IFERROR(K21*L21,0),0) -> 540
A22: Rueda abdominal | B22: MC02 | C22: 10-15 + Fallo | D22: 0 | E22: 15 | F22: 55 | G22: 0 | H22: 15 | I22: 55 | J22: 0 | K22: 15 | L22: 55 | M22: =IFERROR(IFERROR(E22*F22,0)+IFERROR(H22*I22,0)+IFERROR(K22*L22,0),0) -> 2475
A23: TONELAJE TOTAL MC02 | M23: =SUM(M16,M17,M18,M19,M20,M21,M22) -> 11485
A25: MICROCICLO 03
A26: Jalon al pecho con agarre neutro | B26: MC03 | C26: 10-12 | D26: 1 | E26: 10 | F26: 70 | G26: 1 | H26: 10 | I26: 70 | J26: 1 | K26: 10 | L26: 70 | M26: =IFERROR(IFERROR(E26*F26,0)+IFERROR(H26*I26,0)+IFERROR(K26*L26,0),0) -> 2100
A27: Remo en maquina con apoyo en el pecho | B27: MC03 | C27: 10-12 | D27: 1 | E27: 10 | F27: 60 | G27: 1 | H27: 11 | I27: 60 | J27: 1 | K27: 10 | L27: 60 | M27: =IFERROR(IFERROR(E27*F27,0)+IFERROR(H27*I27,0)+IFERROR(K27*L27,0),0) -> 1860
A28: Remo Gironda en polea baja | B28: MC03 | C28: 12-15 + RP | D28: 1 | E28: 12 | F28: 80 | G28: 1 | H28: 11 | I28: 80 | J28: 0 | K28: 10 | L28: 80 | M28: =IFERROR(IFERROR(E28*F28,0)+IFERROR(H28*I28,0)+IFERROR(K28*L28,0),0) -> 2640
A29: Pull-over con cuerda en polea alta | B29: MC03 | C29: 12-15 | D29: 0 | E29: 12 | F29: 30 | G29: 0 | H29: 12 | I29: 30 | J29: 0 | K29: 11 | L29: 35 | M29: =IFERROR(IFERROR(E29*F29,0)+IFERROR(H29*I29,0)+IFERROR(K29*L29,0),0) -> 1105
A30: Pajaros para deltoide posterior en maquina | B30: MC03 | C30: 15-20 + DS | D30: 1 | E30: 12 | F30: 35 | G30: 0 | H30: 12 | I30: 35 | J30: 0 | K30: 12 | L30: 35 | M30: =IFERROR(IFERROR(E30*F30,0)+IFERROR(H30*I30,0)+IFERROR(K30*L30,0),0) -> 1260
A31: Curl Scott en maquina | B31: MC03 | C31: 10-12 + Fallo | D31: 0 | E31: 12 | F31: 15 | G31: 0 | H31: 12 | I31: 15 | J31: 0 | K31: 12 | L31: 15 | M31: =IFERROR(IFERROR(E31*F31,0)+IFERROR(H31*I31,0)+IFERROR(K31*L31,0),0) -> 540
A32: Rueda abdominal | B32: MC03 | C32: 10-15 + Fallo | D32: 0 | E32: 12 | F32: 55 | G32: 0 | H32: 12 | I32: 55 | J32: 0 | K32: 12 | L32: 55 | M32: =IFERROR(IFERROR(E32*F32,0)+IFERROR(H32*I32,0)+IFERROR(K32*L32,0),0) -> 1980
A33: TONELAJE TOTAL MC03 | M33: =SUM(M26,M27,M28,M29,M30,M31,M32) -> 11485
A35: MICROCICLO 04
A36: Jalon al pecho con agarre neutro | B36: MC04 | C36: 10-12 | D36: 1 | E36: 12 | F36: 70 | G36: 1 | H36: 12 | I36: 70 | J36: 1 | K36: 11 | L36: 70 | M36: =IFERROR(IFERROR(E36*F36,0)+IFERROR(H36*I36,0)+IFERROR(K36*L36,0),0) -> 2450
A37: Remo en maquina con apoyo en el pecho | B37: MC04 | C37: 10-12 | D37: 1 | E37: 10 | F37: 80 | G37: 1 | H37: 10 | I37: 80 | J37: 1 | K37: 10 | L37: 80 | M37: =IFERROR(IFERROR(E37*F37,0)+IFERROR(H37*I37,0)+IFERROR(K37*L37,0),0) -> 2400
A38: Remo Gironda en polea baja | B38: MC04 | C38: 12-15 + RP | D38: 1 | E38: 12 | F38: 80 | G38: 1 | H38: 12 | I38: 80 | J38: 0 | K38: 12 | L38: 80 | M38: =IFERROR(IFERROR(E38*F38,0)+IFERROR(H38*I38,0)+IFERROR(K38*L38,0),0) -> 2880
A39: Pull-over con cuerda en polea alta | B39: MC04 | C39: 12-15 | D39: 0 | E39: 12 | F39: 30 | G39: 0 | H39: 12 | I39: 30 | J39: 0 | K39: 12 | L39: 30 | M39: =IFERROR(IFERROR(E39*F39,0)+IFERROR(H39*I39,0)+IFERROR(K39*L39,0),0) -> 1080
A40: Pajaros para deltoide posterior en maquina | B40: MC04 | C40: 15-20 + DS | D40: 1 | E40: 12 | F40: 35 | G40: 0 | H40: 12 | I40: 35 | J40: 0 | K40: 12 | L40: 35 | M40: =IFERROR(IFERROR(E40*F40,0)+IFERROR(H40*I40,0)+IFERROR(K40*L40,0),0) -> 1260
A41: Curl Scott en maquina | B41: MC04 | C41: 10-12 + Fallo | D41: 0 | E41: 12 | F41: 15 | G41: 0 | H41: 12 | I41: 15 | J41: 0 | K41: 12 | L41: 15 | M41: =IFERROR(IFERROR(E41*F41,0)+IFERROR(H41*I41,0)+IFERROR(K41*L41,0),0) -> 540
A42: Rueda abdominal | B42: MC04 | C42: 10-15 + Fallo | D42: 0 | E42: 12 | F42: 55 | G42: 0 | H42: 12 | I42: 55 | J42: 0 | K42: 12 | L42: 55 | M42: =IFERROR(IFERROR(E42*F42,0)+IFERROR(H42*I42,0)+IFERROR(K42*L42,0),0) -> 1980
A43: TONELAJE TOTAL MC04 | M43: =SUM(M36,M37,M38,M39,M40,M41,M42) -> 12590
...

Sheet DAY 3
A1: DAY 3 — MARTES — Pecho + Hombro + Triceps + Core
A2: CALENTAMIENTO (5-8 min)
A3: [ ] Movilidad Munecas | B3: [ ] Rot. Manguito | F3: [ ] Flexiones (Push-ups)
A4: EJERCICIO | B4: MC | C4: REPS OBJETIVO + RP | D4: RIR S1 | E4: Reps S1 | F4: Kg S1 [ | G4: RIR S2 | H4: Reps S2 | I4: Kg S2 | J4: RIR S3 | K4: Reps S3 | L4: Kg S3 | M4: TONELAJE (Auto) | N4: COSAS A COMENTAR | O4: HECHO [ ]
A5: MICROCICLO 01
A6: Press plano en maquina | B6: MC01 | C6: 8-12 | D6: 1 | E6: 0 | F6: 0 | G6: 1 | H6: 0 | I6: 0 | J6: 1 | K6: 0 | L6: 0 | M6: =IFERROR(IFERROR(E6*F6,0)+IFERROR(H6*I6,0)+IFERROR(K6*L6,0),0) -> 0
A7: Press inclinado en multipower | B7: MC01 | C7: 8-12 + RP | D7: 1 | E7: 0 | F7: 0 | G7: 1 | H7: 0 | I7: 0 | J7: 0 | K7: 0 | L7: 0 | M7: =IFERROR(IFERROR(E7*F7,0)+IFERROR(H7*I7,0)+IFERROR(K7*L7,0),0) -> 0
A8: Press declinado en maquina | B8: MC01 | C8: 10-12 | D8: 1 | E8: 0 | F8: 0 | G8: 1 | H8: 0 | I8: 0 | J8: 1 | K8: 0 | L8: 0 | M8: =IFERROR(IFERROR(E8*F8,0)+IFERROR(H8*I8,0)+IFERROR(K8*L8,0),0) -> 0
A9: Aperturas en Pec-Deck | B9: MC01 | C9: 12-15 + DS | D9: 1 | E9: 0 | F9: 0 | G9: 0 | H9: 0 | I9: 0 | J9: 0 | K9: 0 | L9: 0 | M9: =IFERROR(IFERROR(E9*F9,0)+IFERROR(H9*I9,0)+IFERROR(K9*L9,0),0) -> 0
A10: Elevaciones laterales con mancuerna | B10: MC01 | C10: 15-20 | D10: 0 | E10: 0 | F10: 0 | G10: 0 | H10: 0 | I10: 0 | J10: 0 | K10: 0 | L10: 0 | M10: =IFERROR(IFERROR(E10*F10,0)+IFERROR(H10*I10,0)+IFERROR(K10*L10,0),0) -> 0
A11: Elevaciones laterales en polea baja | B11: MC01 | C11: 15-20 | D11: 0 | E11: 0 | F11: 0 | G11: 0 | H11: 0 | I11: 0 | J11: 0 | K11: 0 | L11: 0 | M11: =IFERROR(IFERROR(E11*F11,0)+IFERROR(H11*I11,0)+IFERROR(K11*L11,0),0) -> 0
A12: Elevaciones laterales en polea media | B12: MC01 | C12: 15-20 | D12: 0 | E12: 0 | F12: 0 | G12: 0 | H12: 0 | I12: 0 | J12: 0 | K12: 0 | L12: 0 | M12: =IFERROR(IFERROR(E12*F12,0)+IFERROR(H12*I12,0)+IFERROR(K12*L12,0),0) -> 0
A13: Extension de triceps en polea alta | B13: MC01 | C13: 12-15 + Fallo | D13: 0 | E13: 0 | F13: 0 | G13: 0 | H13: 0 | I13: 0 | J13: 0 | K13: 0 | L13: 0 | M13: =IFERROR(IFERROR(E13*F13,0)+IFERROR(H13*I13,0)+IFERROR(K13*L13,0),0) -> 0
A14: Extensiones Katana en polea | B14: MC01 | C14: 12-15 + DS | D14: 1 | E14: 0 | F14: 0 | G14: 0 | H14: 0 | I14: 0 | J14: 0 | K14: 0 | L14: 0 | M14: =IFERROR(IFERROR(E14*F14,0)+IFERROR(H14*I14,0)+IFERROR(K14*L14,0),0) -> 0
A15: Crunch abdominal en polea | B15: MC01 | C15: 15-20 + Fallo | D15: 0 | E15: 0 | F15: 0 | G15: 0 | H15: 0 | I15: 0 | J15: 0 | K15: 0 | L15: 0 | M15: =IFERROR(IFERROR(E15*F15,0)+IFERROR(H15*I15,0)+IFERROR(K15*L15,0),0) -> 0
A16: TONELAJE TOTAL MC01 | M16: =SUM(M6,M7,M8,M9,M10,M11,M12,M13,M14,M15) -> 0
A18: MICROCICLO 02
A19: Press plano en maquina | B19: MC02 | C19: 8-12 | D19: 1 | E19: 10 | F19: 40 | G19: 1 | H19: 10 | I19: 40 | J19: 1 | K19: 10 | L19: 40 | M19: =IFERROR(IFERROR(E19*F19,0)+IFERROR(H19*I19,0)+IFERROR(K19*L19,0),0) -> 1200
A20: Press inclinado en multipower | B20: MC02 | C20: 8-12 + RP | D20: 1 | E20: 8 | F20: 50 | G20: 1 | H20: 8 | I20: 50 | J20: 0 | K20: 15 | L20: 50 | M20: =IFERROR(IFERROR(E20*F20,0)+IFERROR(H20*I20,0)+IFERROR(K20*L20,0),0) -> 1550
A21: Press declinado en maquina | B21: MC02 | C21: 10-12 | D21: 1 | E21: 10 | F21: 42.5 | G21: 1 | H21: 10 | I21: 42.5 | J21: 1 | K21: 10 | L21: 42.5 | M21: =IFERROR(IFERROR(E21*F21,0)+IFERROR(H21*I21,0)+IFERROR(K21*L21,0),0) -> 1275
A22: Aperturas en Pec-Deck | B22: MC02 | C22: 12-15 + DS | D22: 1 | E22: 12 | F22: 42.5 | G22: 0 | H22: 12 | I22: 42.5 | J22: 0 | K22: 12 | L22: 42.5 | M22: =IFERROR(IFERROR(E22*F22,0)+IFERROR(H22*I22,0)+IFERROR(K22*L22,0),0) -> 1530
A23: Elevaciones laterales con mancuerna | B23: MC02 | C23: 15-20 | D23: 0 | E23: 15 | F23: 9 | G23: 0 | H23: 15 | I23: 9 | J23: 0 | K23: 15 | L23: 9 | M23: =IFERROR(IFERROR(E23*F23,0)+IFERROR(H23*I23,0)+IFERROR(K23*L23,0),0) -> 405
A24: Elevaciones laterales en polea baja | B24: MC02 | C24: 15-20 | D24: 0 | E24: 15 | F24: 11.5 | G24: 0 | H24: 15 | I24: 11.5 | J24: 0 | K24: 15 | L24: 11.5 | M24: =IFERROR(IFERROR(E24*F24,0)+IFERROR(H24*I24,0)+IFERROR(K24*L24,0),0) -> 517.5
A25: Elevaciones laterales en polea media | B25: MC02 | C25: 15-20 | D25: 0 | E25: 15 | F25: 15 | G25: 0 | H25: 15 | I25: 15 | J25: 0 | K25: 15 | L25: 15 | M25: =IFERROR(IFERROR(E25*F25,0)+IFERROR(H25*I25,0)+IFERROR(K25*L25,0),0) -> 675
A26: Extension de triceps en polea alta | B26: MC02 | C26: 12-15 + Fallo | D26: 0 | E26: 12 | F26: 20 | G26: 0 | H26: 13 | I26: 20 | J26: 0 | K26: 13 | L26: 20 | M26: =IFERROR(IFERROR(E26*F26,0)+IFERROR(H26*I26,0)+IFERROR(K26*L26,0),0) -> 760
A27: Extensiones Katana en polea | B27: MC02 | C27: 12-15 + DS | D27: 1 | E27: 12 | F27: 15 | G27: 0 | H27: 10 | I27: 15 | J27: 0 | K27: 10 | L27: 15 | M27: =IFERROR(IFERROR(E27*F27,0)+IFERROR(H27*I27,0)+IFERROR(K27*L27,0),0) -> 480
A28: Crunch abdominal en polea | B28: MC02 | C28: 15-20 + Fallo | D28: 0 | E28: 16 | F28: 57.5 | G28: 0 | H28: 14 | I28: 62.5 | J28: 0 | K28: 14 | L28: 57.5 | M28: =IFERROR(IFERROR(E28*F28,0)+IFERROR(H28*I28,0)+IFERROR(K28*L28,0),0) -> 2600
A29: TONELAJE TOTAL MC02 | M29: =SUM(M19,M20,M21,M22,M23,M24,M25,M26,M27,M28) -> 10992.5
A31: MICROCICLO 03
A32: Press plano en maquina | B32: MC03 | C32: 8-12 | D32: 1 | E32: 8 | F32: 60 | G32: 1 | H32: 8 | I32: 60 | J32: 1 | K32: 7 | L32: 60 | M32: =IFERROR(IFERROR(E32*F32,0)+IFERROR(H32*I32,0)+IFERROR(K32*L32,0),0) -> 1380
A33: Press inclinado en multipower | B33: MC03 | C33: 8-12 + RP | D33: 1 | E33: 8 | F33: 50 | G33: 1 | H33: 8 | I33: 50 | J33: 0 | K33: 8 | L33: 50 | M33: =IFERROR(IFERROR(E33*F33,0)+IFERROR(H33*I33,0)+IFERROR(K33*L33,0),0) -> 1200
A34: Press declinado en maquina | B34: MC03 | C34: 10-12 | D34: 1 | E34: 12 | F34: 42.5 | G34: 1 | H34: 10 | I34: 50 | J34: 1 | K34: 10 | L34: 50 | M34: =IFERROR(IFERROR(E34*F34,0)+IFERROR(H34*I34,0)+IFERROR(K34*L34,0),0) -> 1510
A35: Aperturas en Pec-Deck | B35: MC03 | C35: 12-15 + DS | D35: 1 | E35: 12 | F35: 42.5 | G35: 0 | H35: 12 | I35: 42.5 | J35: 0 | K35: 12 | L35: 42.5 | M35: =IFERROR(IFERROR(E35*F35,0)+IFERROR(H35*I35,0)+IFERROR(K35*L35,0),0) -> 1530
A36: Elevaciones laterales con mancuerna | B36: MC03 | C36: 15-20 | D36: 0 | E36: 15 | F36: 9 | G36: 0 | H36: 15 | I36: 9 | J36: 0 | K36: 13 | L36: 10 | M36: =IFERROR(IFERROR(E36*F36,0)+IFERROR(H36*I36,0)+IFERROR(K36*L36,0),0) -> 400
A37: Elevaciones laterales en polea baja | B37: MC03 | C37: 15-20 | D37: 0 | E37: 15 | F37: 12.5 | G37: 0 | H37: 15 | I37: 12.5 | J37: 0 | K37: 15 | L37: 12.5 | M37: =IFERROR(IFERROR(E37*F37,0)+IFERROR(H37*I37,0)+IFERROR(K37*L37,0),0) -> 562.5
A38: Elevaciones laterales en polea media | B38: MC03 | C38: 15-20 | D38: 0 | E38: 15 | F38: 20 | G38: 0 | H38: 20 | I38: 15 | J38: 0 | K38: 15 | L38: 20 | M38: =IFERROR(IFERROR(E38*F38,0)+IFERROR(H38*I38,0)+IFERROR(K38*L38,0),0) -> 900
A39: Extension de triceps en polea alta | B39: MC03 | C39: 12-15 + Fallo | D39: 0 | E39: 12 | F39: 25 | G39: 0 | H39: 12 | I39: 25 | J39: 0 | K39: 12 | L39: 25 | M39: =IFERROR(IFERROR(E39*F39,0)+IFERROR(H39*I39,0)+IFERROR(K39*L39,0),0) -> 900
A40: Extensiones Katana en polea | B40: MC03 | C40: 12-15 + DS | D40: 1 | E40: 12 | F40: 15 | G40: 0 | H40: 12 | I40: 15 | J40: 0 | K40: 12 | L40: 15 | M40: =IFERROR(IFERROR(E40*F40,0)+IFERROR(H40*I40,0)+IFERROR(K40*L40,0),0) -> 540
A41: Crunch abdominal en polea | B41: MC03 | C41: 15-20 + Fallo | D41: 0 | E41: 16 | F41: 57.5 | G41: 0 | H41: 16 | I41: 57.5 | J41: 0 | K41: 16 | L41: 57.5 | M41: =IFERROR(IFERROR(E41*F41,0)+IFERROR(H41*I41,0)+IFERROR(K41*L41,0),0) -> 2760
A42: TONELAJE TOTAL MC03 | M42: =SUM(M32,M33,M34,M35,M36,M37,M38,M39,M40,M41) -> 11682.5
...

Sheet DAY 4
A1: DAY 4 — MIERCOLES — Pierna Compuesta + Core
A2: CALENTAMIENTO (5-8 min)
A3: [ ] Sentadilla Profunda hold 3s | B3: [ ] Dinamico Flexores Cadera | F3: [ ] Movilidad Tobillo
A4: EJERCICIO | B4: MC | C4: REPS OBJETIVO + RP | D4: RIR S1 | E4: Reps S1 | F4: Kg S1 | G4: RIR S2 | H4: Reps S2 | I4: Kg S2 | J4: RIR S3 | K4: Reps S3 | L4: Kg S3 | M4: TONELAJE (Auto) | N4: COSAS A COMENTAR | O4: HECHO [ ]
A5: MICROCICLO 01
A6: Peso muerto rumano con mancuernas | B6: MC01 | C6: 10-12 | D6: 1 | E6: 12 | F6: 17.5 | G6: 1 | H6: 12 | I6: 17.5 | J6: 1 | K6: 12 | L6: 17.5 | M6: =IFERROR(IFERROR(E6*F6,0)+IFERROR(H6*I6,0)+IFERROR(K6*L6,0),0) -> 630
A7: Prensa de piernas inclinada | B7: MC01 | C7: 10-12 + Fallo | D7: 0 | E7: 12 | F7: 150 | G7: 0 | H7: 10 | I7: 150 | J7: 0 | K7: 10 | L7: 150 | M7: =IFERROR(IFERROR(E7*F7,0)+IFERROR(H7*I7,0)+IFERROR(K7*L7,0),0) -> 4800
A8: Extension de cuadriceps en maquina | B8: MC01 | C8: 12-15 + DS | D8: 1 | E8: 12 | F8: 60 | G8: 0 | H8: 12 | I8: 60 | J8: 0 | K8: 12 | L8: 60 | M8: =IFERROR(IFERROR(E8*F8,0)+IFERROR(H8*I8,0)+IFERROR(K8*L8,0),0) -> 2160
A9: Curl femoral sentado en maquina | B9: MC01 | C9: 12-15 + RP | D9: 1 | E9: 13 | F9: 47.5 | G9: 1 | H9: 12 | I9: 47.5 | J9: 0 | K9: 12 | L9: 47.5 | M9: =IFERROR(IFERROR(E9*F9,0)+IFERROR(H9*I9,0)+IFERROR(K9*L9,0),0) -> 1757.5
A10: Aductores en maquina | B10: MC01 | C10: 15-20 | D10: 0 | E10: 15 | F10: 35 | G10: 0 | H10: 15 | I10: 35 | J10: 0 | K10: 13 | L10: 35 | M10: =IFERROR(IFERROR(E10*F10,0)+IFERROR(H10*I10,0)+IFERROR(K10*L10,0),0) -> 1505
A11: Gemelos en prensa | B11: MC01 | C11: 15-20 + Fallo | D11: 0 | E11: 18 | F11: 100 | G11: 0 | H11: 18 | I11: 100 | J11: 0 | K11: 16 | L11: 100 | M11: =IFERROR(IFERROR(E11*F11,0)+IFERROR(H11*I11,0)+IFERROR(K11*L11,0),0) -> 5200
A12: Elevaciones de piernas tumbado | B12: MC01 | C12: 12-15 + Fallo | D12: 0 | E12: 12 | F12: 50 | G12: 0 | H12: 12 | I12: 50 | J12: 0 | K12: 12 | L12: 50 | M12: =IFERROR(IFERROR(E12*F12,0)+IFERROR(H12*I12,0)+IFERROR(K12*L12,0),0) -> 1800
A13: TONELAJE TOTAL MC01 | M13: =SUM(M6,M7,M8,M9,M10,M11,M12) -> 17852.5
A15: MICROCICLO 02
A16: Peso muerto rumano con mancuernas | B16: MC02 | C16: 10-12 | D16: 1 | E16: 12 | F16: 15 | G16: 1 | H16: 12 | I16: 15 | J16: 1 | K16: 12 | L16: 15 | M16: =IFERROR(IFERROR(E16*F16,0)+IFERROR(H16*I16,0)+IFERROR(K16*L16,0),0) -> 540 | N16: no habían mancuernas de 17,5
A17: Prensa de piernas inclinada | B17: MC02 | C17: 10-12 + Fallo | D17: 0 | E17: 12 | F17: 150 | G17: 0 | H17: 9 | I17: 150 | J17: 0 | K17: 10 | L17: 150 | M17: =IFERROR(IFERROR(E17*F17,0)+IFERROR(H17*I17,0)+IFERROR(K17*L17,0),0) -> 4650
A18: Extension de cuadriceps en maquina | B18: MC02 | C18: 12-15 + DS | D18: 1 | E18: 12 | F18: 60 | G18: 0 | H18: 12 | I18: 60 | J18: 0 | K18: 12 | L18: 60 | M18: =IFERROR(IFERROR(E18*F18,0)+IFERROR(H18*I18,0)+IFERROR(K18*L18,0),0) -> 2160
A19: Curl femoral sentado en maquina | B19: MC02 | C19: 12-15 + RP | D19: 1 | E19: 12 | F19: 47.5 | G19: 1 | H19: 12 | I19: 47.5 | J19: 0 | K19: 12 | L19: 47.5 | M19: =IFERROR(IFERROR(E19*F19,0)+IFERROR(H19*I19,0)+IFERROR(K19*L19,0),0) -> 1710
A20: Aductores en maquina | B20: MC02 | C20: 15-20 | D20: 0 | E20: 15 | F20: 35 | G20: 0 | H20: 15 | I20: 35 | J20: 0 | K20: 15 | L20: 35 | M20: =IFERROR(IFERROR(E20*F20,0)+IFERROR(H20*I20,0)+IFERROR(K20*L20,0),0) -> 1575
A21: Gemelos en prensa | B21: MC02 | C21: 15-20 + Fallo | D21: 0 | E21: 18 | F21: 100 | G21: 0 | H21: 18 | I21: 100 | J21: 0 | K21: 18 | L21: 100 | M21: =IFERROR(IFERROR(E21*F21,0)+IFERROR(H21*I21,0)+IFERROR(K21*L21,0),0) -> 5400
